Workbook

Sheet Grid de recoleccion
A1: Grid de recolección — corpus multi-dominio v2 (5 medios × 5 dominios, 500 oraciones)
A2: Recolección CERRADA y auditada. Los objetivos reflejan exactamente lo recolectado: 100 oraciones por dominio, 500 en total. El % de avance mide la ANOTACIÓN: arranca en 0% y sube a medida que se llena la columna 'direccion' de cada oración en la hoja 'Corpus - oraciones'.
A4: Medio | B4: Tema | C4: Objetivo oraciones (dura) | D4: Objetivo oraciones (opinión/análisis) | E4: Objetivo total | F4: Artículos de origen (dura) | G4: Artículos de origen (opinión) | H4: Oraciones ya anotadas | I4: % avance | J4: Estado | K4: Notas
A5: Infobae Colombia | B5: Política | C5: 13 | D5: 0 | E5: =C5+D5 | F5: 6 | G5: 0 | H5: =SUMIFS('Corpus - oraciones'!$AD$5:$AD$600,'Corpus - oraciones'!$C$5:$C$600,A5,'Corpus - oraciones'!$D$5:$D$600,B5) | I5: =IFERROR(H5/E5,0) | J5: Pendiente | K5: Infobae no tiene sección de opinión propia de Colombia: su cuota es 100% noticia dura.
A6: El Tiempo | B6: Política | C6: 10 | D6: 6 | E6: =C6+D6 | F6: 6 | G6: 1 | H6: =SUMIFS('Corpus - oraciones'!$AD$5:$AD$600,'Corpus - oraciones'!$C$5:$C$600,A6,'Corpus - oraciones'!$D$5:$D$600,B6) | I6: =IFERROR(H6/E6,0) | J6: Pendiente | K6: Subset curado de las 500 oraciones del corpus original (sub-temas Transición/EEUU/Reformas/Seguridad, sin Terremoto).
A7: El Espectador | B7: Política | C7: 20 | D7: 0 | E7: =C7+D7 | F7: 4 | G7: 0 | H7: =SUMIFS('Corpus - oraciones'!$AD$5:$AD$600,'Corpus - oraciones'!$C$5:$C$600,A7,'Corpus - oraciones'!$D$5:$D$600,B7) | I7: =IFERROR(H7/E7,0) | J7: Pendiente | K7: Subset curado de las 500 oraciones originales (Transición/EEUU/Reformas/Seguridad, sin Terremoto).
A8: La Silla Vacía | B8: Política | C8: 2 | D8: 9 | E8: =C8+D8 | F8: 2 | G8: 9 | H8: =SUMIFS('Corpus - oraciones'!$AD$5:$AD$600,'Corpus - oraciones'!$C$5:$C$600,A8,'Corpus - oraciones'!$D$5:$D$600,B8) | I8: =IFERROR(H8/E8,0) | J8: Pendiente | K8: Subset curado de las 500 oraciones del corpus original (sub-temas Transición/EEUU/Reformas/Seguridad, sin Terremoto).
A9: Semana | B9: Política | C9: 30 | D9: 10 | E9: =C9+D9 | F9: 3 | G9: 1 | H9: =SUMIFS('Corpus - oraciones'!$AD$5:$AD$600,'Corpus - oraciones'!$C$5:$C$600,A9,'Corpus - oraciones'!$D$5:$D$600,B9) | I9: =IFERROR(H9/E9,0) | J9: Pendiente | K9: Subset curado de las 500 oraciones del corpus original (sub-temas Transición/EEUU/Reformas/Seguridad, sin Terremoto).
A10: Infobae Colombia | B10: Economía y negocios | C10: 20 | D10: 0 | E10: =C10+D10 | F10: 3 | G10: 0 | H10: =SUMIFS('Corpus - oraciones'!$AD$5:$AD$600,'Corpus - oraciones'!$C$5:$C$600,A10,'Corpus - oraciones'!$D$5:$D$600,B10) | I10: =IFERROR(H10/E10,0) | J10: Pendiente
A11: El Tiempo | B11: Economía y negocios | C11: 14 | D11: 6 | E11: =C11+D11 | F11: 2 | G11: 1 | H11: =SUMIFS('Corpus - oraciones'!$AD$5:$AD$600,'Corpus - oraciones'!$C$5:$C$600,A11,'Corpus - oraciones'!$D$5:$D$600,B11) | I11: =IFERROR(H11/E11,0) | J11: Pendiente
A12: El Espectador | B12: Economía y negocios | C12: 6 | D12: 14 | E12: =C12+D12 | F12: 1 | G12: 1 | H12: =SUMIFS('Corpus - oraciones'!$AD$5:$AD$600,'Corpus - oraciones'!$C$5:$C$600,A12,'Corpus - oraciones'!$D$5:$D$600,B12) | I12: =IFERROR(H12/E12,0) | J12: Pendiente
A13: La Silla Vacía | B13: Economía y negocios | C13: 8 | D13: 12 | E13: =C13+D13 | F13: 2 | G13: 1 | H13: =SUMIFS('Corpus - oraciones'!$AD$5:$AD$600,'Corpus - oraciones'!$C$5:$C$600,A13,'Corpus - oraciones'!$D$5:$D$600,B13) | I13: =IFERROR(H13/E13,0) | J13: Pendiente
A14: Semana | B14: Economía y negocios | C14: 10 | D14: 10 | E14: =C14+D14 | F14: 2 | G14: 1 | H14: =SUMIFS('Corpus - oraciones'!$AD$5:$AD$600,'Corpus - oraciones'!$C$5:$C$600,A14,'Corpus - oraciones'!$D$5:$D$600,B14) | I14: =IFERROR(H14/E14,0) | J14: Pendiente
A15: Infobae Colombia | B15: Salud | C15: 20 | D15: 0 | E15: =C15+D15 | F15: 3 | G15: 0 | H15: =SUMIFS('Corpus - oraciones'!$AD$5:$AD$600,'Corpus - oraciones'!$C$5:$C$600,A15,'Corpus - oraciones'!$D$5:$D$600,B15) | I15: =IFERROR(H15/E15,0) | J15: Pendiente
A16: El Tiempo | B16: Salud | C16: 14 | D16: 6 | E16: =C16+D16 | F16: 2 | G16: 1 | H16: =SUMIFS('Corpus - oraciones'!$AD$5:$AD$600,'Corpus - oraciones'!$C$5:$C$600,A16,'Corpus - oraciones'!$D$5:$D$600,B16) | I16: =IFERROR(H16/E16,0) | J16: Pendiente
A17: El Espectador | B17: Salud | C17: 6 | D17: 14 | E17: =C17+D17 | F17: 1 | G17: 1 | H17: =SUMIFS('Corpus - oraciones'!$AD$5:$AD$600,'Corpus - oraciones'!$C$5:$C$600,A17,'Corpus - oraciones'!$D$5:$D$600,B17) | I17: =IFERROR(H17/E17,0) | J17: Pendiente
A18: La Silla Vacía | B18: Salud | C18: 8 | D18: 12 | E18: =C18+D18 | F18: 1 | G18: 1 | H18: =SUMIFS('Corpus - oraciones'!$AD$5:$AD$600,'Corpus - oraciones'!$C$5:$C$600,A18,'Corpus - oraciones'!$D$5:$D$600,B18) | I18: =IFERROR(H18/E18,0) | J18: Pendiente
A19: Semana | B19: Salud | C19: 10 | D19: 10 | E19: =C19+D19 | F19: 1 | G19: 1 | H19: =SUMIFS('Corpus - oraciones'!$AD$5:$AD$600,'Corpus - oraciones'!$C$5:$C$600,A19,'Corpus - oraciones'!$D$5:$D$600,B19) | I19: =IFERROR(H19/E19,0) | J19: Pendiente
A20: Infobae Colombia | B20: Medio ambiente | C20: 20 | D20: 0 | E20: =C20+D20 | F20: 2 | G20: 0 | H20: =SUMIFS('Corpus - oraciones'!$AD$5:$AD$600,'Corpus - oraciones'!$C$5:$C$600,A20,'Corpus - oraciones'!$D$5:$D$600,B20) | I20: =IFERROR(H20/E20,0) | J20: Pendiente
A21: El Tiempo | B21: Medio ambiente | C21: 14 | D21: 6 | E21: =C21+D21 | F21: 3 | G21: 1 | H21: =SUMIFS('Corpus - oraciones'!$AD$5:$AD$600,'Corpus - oraciones'!$C$5:$C$600,A21,'Corpus - oraciones'!$D$5:$D$600,B21) | I21: =IFERROR(H21/E21,0) | J21: Pendiente
A22: El Espectador | B22: Medio ambiente | C22: 20 | D22: 0 | E22: =C22+D22 | F22: 2 | G22: 0 | H22: =SUMIFS('Corpus - oraciones'!$AD$5:$AD$600,'Corpus - oraciones'!$C$5:$C$600,A22,'Corpus - oraciones'!$D$5:$D$600,B22) | I22: =IFERROR(H22/E22,0) | J22: Pendiente | K22: El artículo de análisis sobre fracking resultó ser nota explicativa neutral (auditoría): se clasificó como 'Noticia dura'; por eso la celda quedó 20 dura / 0 opinión.
A23: La Silla Vacía | B23: Medio ambiente | C23: 8 | D23: 12 | E23: =C23+D23 | F23: 2 | G23: 2 | H23: =SUMIFS('Corpus - oraciones'!$AD$5:$AD$600,'Corpus - oraciones'!$C$5:$C$600,A23,'Corpus - oraciones'!$D$5:$D$600,B23) | I23: =IFERROR(H23/E23,0) | J23: Pendiente
A24: Semana | B24: Medio ambiente | C24: 10 | D24: 10 | E24: =C24+D24 | F24: 1 | G24: 1 | H24: =SUMIFS('Corpus - oraciones'!$AD$5:$AD$600,'Corpus - oraciones'!$C$5:$C$600,A24,'Corpus - oraciones'!$D$5:$D$600,B24) | I24: =IFERROR(H24/E24,0) | J24: Pendiente
A25: Infobae Colombia | B25: Deportes | C25: 25 | D25: 0 | E25: =C25+D25 | F25: 5 | G25: 0 | H25: =SUMIFS('Corpus - oraciones'!$AD$5:$AD$600,'Corpus - oraciones'!$C$5:$C$600,A25,'Corpus - oraciones'!$D$5:$D$600,B25) | I25: =IFERROR(H25/E25,0) | J25: Pendiente
A26: El Tiempo | B26: Deportes | C26: 17 | D26: 14 | E26: =C26+D26 | F26: 3 | G26: 2 | H26: =SUMIFS('Corpus - oraciones'!$AD$5:$AD$600,'Corpus - oraciones'!$C$5:$C$600,A26,'Corpus - oraciones'!$D$5:$D$600,B26) | I26: =IFERROR(H26/E26,0) | J26: Pendiente
A27: El Espectador | B27: Deportes | C27: 8 | D27: 23 | E27: =C27+D27 | F27: 2 | G27: 3 | H27: =SUMIFS('Corpus - oraciones'!$AD$5:$AD$600,'Corpus - oraciones'!$C$5:$C$600,A27,'Corpus - oraciones'!$D$5:$D$600,B27) | I27: =IFERROR(H27/E27,0) | J27: Pendiente
A28: La Silla Vacía | B28: Deportes | C28: 0 | D28: 0 | E28: =C28+D28 | F28: 0 | G28: 0 | H28: =SUMIFS('Corpus - oraciones'!$AD$5:$AD$600,'Corpus - oraciones'!$C$5:$C$600,A28,'Corpus - oraciones'!$D$5:$D$600,B28) | I28: =IFERROR(H28/E28,0) | J28: Pendiente | K28: La Silla Vacía no tiene cobertura deportiva activa 2025-2026 (verificado): su cuota se redistribuyó entre los otros 4 medios.
A29: Semana | B29: Deportes | C29: 13 | D29: 0 | E29: =C29+D29 | F29: 2 | G29: 0 | H29: =SUMIFS('Corpus - oraciones'!$AD$5:$AD$600,'Corpus - oraciones'!$C$5:$C$600,A29,'Corpus - oraciones'!$D$5:$D$600,B29) | I29: =IFERROR(H29/E29,0) | J29: Pendiente | K29: Semana no tiene columnistas de opinión deportiva (verificado): su cuota de opinión se redistribuyó a El Tiempo y El Espectador.
A30: TOTAL | C30: =SUM(C5:C29) | D30: =SUM(D5:D29) | E30: =SUM(E5:E29) | H30: =SUM(H5:H29) | I30: =IFERROR(H30/E30,0)

Sheet Resumen
A1: Resumen por medio y por dominio — corpus v2
A3: Por medio
A4: Medio | B4: Objetivo total | C4: Oraciones anotadas | D4: % avance
A5: Infobae Colombia | B5: =SUMIF('Grid de recoleccion'!A:A,A5,'Grid de recoleccion'!E:E) | C5: =SUMIF('Grid de recoleccion'!A:A,A5,'Grid de recoleccion'!H:H) | D5: =IFERROR(C5/B5,0)
A6: El Tiempo | B6: =SUMIF('Grid de recoleccion'!A:A,A6,'Grid de recoleccion'!E:E) | C6: =SUMIF('Grid de recoleccion'!A:A,A6,'Grid de recoleccion'!H:H) | D6: =IFERROR(C6/B6,0)
A7: El Espectador | B7: =SUMIF('Grid de recoleccion'!A:A,A7,'Grid de recoleccion'!E:E) | C7: =SUMIF('Grid de recoleccion'!A:A,A7,'Grid de recoleccion'!H:H) | D7: =IFERROR(C7/B7,0)
A8: La Silla Vacía | B8: =SUMIF('Grid de recoleccion'!A:A,A8,'Grid de recoleccion'!E:E) | C8: =SUMIF('Grid de recoleccion'!A:A,A8,'Grid de recoleccion'!H:H) | D8: =IFERROR(C8/B8,0)
A9: Semana | B9: =SUMIF('Grid de recoleccion'!A:A,A9,'Grid de recoleccion'!E:E) | C9: =SUMIF('Grid de recoleccion'!A:A,A9,'Grid de recoleccion'!H:H) | D9: =IFERROR(C9/B9,0)
A10: TOTAL | B10: =SUM(B5:B9) | C10: =SUM(C5:C9) | D10: =IFERROR(C10/B10,0)
A13: Por dominio
A14: Dominio | B14: Objetivo total | C14: Oraciones anotadas | D14: % avance
A15: Política | B15: =SUMIF('Grid de recoleccion'!B:B,A15,'Grid de recoleccion'!E:E) | C15: =SUMIF('Grid de recoleccion'!B:B,A15,'Grid de recoleccion'!H:H) | D15: =IFERROR(C15/B15,0)
A16: Economía y negocios | B16: =SUMIF('Grid de recoleccion'!B:B,A16,'Grid de recoleccion'!E:E) | C16: =SUMIF('Grid de recoleccion'!B:B,A16,'Grid de recoleccion'!H:H) | D16: =IFERROR(C16/B16,0)
A17: Salud | B17: =SUMIF('Grid de recoleccion'!B:B,A17,'Grid de recoleccion'!E:E) | C17: =SUMIF('Grid de recoleccion'!B:B,A17,'Grid de recoleccion'!H:H) | D17: =IFERROR(C17/B17,0)
A18: Medio ambiente | B18: =SUMIF('Grid de recoleccion'!B:B,A18,'Grid de recoleccion'!E:E) | C18: =SUMIF('Grid de recoleccion'!B:B,A18,'Grid de recoleccion'!H:H) | D18: =IFERROR(C18/B18,0)
A19: Deportes | B19: =SUMIF('Grid de recoleccion'!B:B,A19,'Grid de recoleccion'!E:E) | C19: =SUMIF('Grid de recoleccion'!B:B,A19,'Grid de recoleccion'!H:H) | D19: =IFERROR(C19/B19,0)
A20: TOTAL | B20: =SUM(B15:B19) | C20: =SUM(C15:C19) | D20: =IFERROR(C20/B20,0)

Sheet Leyenda
A1: Cómo usar este archivo
A3: Qué es este archivo | B3: Corpus multi-dominio v2: 500 oraciones reales de 5 medios colombianos (Infobae Colombia, El Tiempo, El Espectador, La Silla Vacía, Semana) repartidas en 5 dominios de 100 oraciones cada uno: Política, Economía y negocios, Salud, Medio ambiente y Deportes. La recolección está cerrada y auditada; lo que falta es la ANOTACIÓN.
A4: Hoja 'Corpus - oraciones' | B4: Es la hoja de trabajo: una fila por oración, 500 filas (de la fila 5 a la 504). Las columnas en GRIS (A–I, más aux y url_fuente) vienen dadas y NO se editan. Las columnas en AMARILLO (J a AC) son las que llena el anotador: las 9 categorías con su span, direccion y actor_objetivo.
A5: Unidad de anotación | B5: La oración. Toda oración revisada recibe exactamente una fila, incluso si todas las categorías quedan en FALSE: las oraciones neutras son tan necesarias como las sesgadas, no se omiten.
A6: Esquema de anotación | B6: 9 categorías booleanas, cada una con su columna de span al lado (se llena solo si la categoría quedó en TRUE): 5 léxicas J1 (verbo_factivo, verbo_asertivo, palabra_subjetiva, hedge, etiqueta_valorativa) y 4 discursivas J2 (sensacionalismo, mind_reading, falta_atribucion, opinion_como_hecho). Se suman direccion (favorece / perjudica / neutral) y actor_objetivo (lista cerrada de 9 opciones, obligatorio si direccion no es neutral). En total, 11 campos por oración.
A7: Listas desplegables | B7: medio, tema, género, direccion y las 9 categorías booleanas tienen lista desplegable: seleccione siempre de la lista, no escriba a mano.
A8: Ejemplo de fila anotada | B8: Oración: «El Gobierno impuso la polémica reforma tributaria pese a las advertencias de los gremios, sabiendo que afectaría directamente a la clase media.» → tres mecanismos en la MISMA fila: palabra_subjetiva = TRUE con span «impuso»; etiqueta_valorativa = TRUE con span «polémica»; mind_reading = TRUE con span «sabiendo que afectaría directamente a la clase media». Las otras 6 categorías quedan en FALSE. direccion = perjudica y actor_objetivo = Gobierno / Ejecutivo. Las categorías no son excluyentes: se marcan todas las que apliquen, cada una con su propio span, y la oración sigue ocupando una sola fila.
A9: Ejemplo de oración neutral | B9: Oración: «El Banco de la República publicará el informe de inflación el próximo martes.» → las 9 categorías en FALSE, sin span, direccion = neutral y actor_objetivo vacío. La fila se conserva igual: las oraciones neutras son parte del corpus, no se omiten.
A10: Hoja 'Grid de recoleccion' | B10: Tablero de control por medio × dominio. 'Objetivo' = lo realmente recolectado (ya cerrado). 'Artículos de origen' indica de cuántos artículos distintos salieron esas oraciones. 'Oraciones ya anotadas' y el '% avance' se calculan solos: cuentan las oraciones que ya tienen 'direccion' llena, así que arrancan en 0% y llegan a 100% cuando se termina esa celda. Edite solo Estado (Pendiente / En progreso / Completo) y Notas.
A11: Hoja 'Resumen' | B11: Se calcula sola a partir del Grid: totales por medio y por dominio. Solo lectura.
A12: IDs | B12: articulo_id va de ART_001 a ART_089, ordenados por dominio → medio → género. oracion_id = articulo_id + _S## con numeración contigua dentro de cada artículo (S01, S02, ...). Un mismo articulo_id = un mismo artículo real (misma url_fuente).
A13: Contexto | B13: oracion_anterior y oracion_siguiente traen las oraciones vecinas reales del mismo artículo, para que el anotador juzgue en contexto. Están vacías cuando la oración es la primera o la última capturada del artículo.
A14: actor_objetivo (lista cerrada) | B14: Se llena SOLO si direccion != neutral; si direccion = neutral, déjelo vacío. Nueve opciones: Gobierno / Ejecutivo; Oposición / partidos políticos; Instituciones del Estado; Empresas y gremios; Sindicatos y organizaciones sociales; Ciudadanía afectada; Actores del deporte; Actor internacional; Otro / no identificable. Regla clave: anote el ROL institucional, no la persona (Petro como presidente → Gobierno / Ejecutivo; Néstor Lorenzo como DT → Actores del deporte).

Sheet Corpus - oraciones
A1: Corpus multi-dominio v2 — una fila por oración (esquema completo: 9 categorías léxico/discursivo)
A2: 500 oraciones reales de 5 medios colombianos en 5 dominios (Política, Economía y negocios, Salud, Medio ambiente, Deportes), 100 por dominio. Datos desde la fila 5. GRIS = viene dado, no se toca. AMARILLO = lo llena el anotador (columnas J a AC). La columna AD es auxiliar y alimenta el Grid; la AE trae la URL del artículo original.
A4: articulo_id | B4: oracion_id | C4: medio | D4: tema | E4: género (dura/opinión) | F4: fecha_ publicación | G4: oracion_texto | H4: oracion_anterior | I4: oracion_siguiente | J4: verbo_factivo (J1) | K4: verbo_factivo_span | L4: verbo_asertivo (J1) | M4: verbo_asertivo_span | N4: palabra_subjetiva (J1) | O4: palabra_subjetiva_span | P4: hedge (J1) | Q4: hedge_span | R4: etiqueta_valorativa (J1) | S4: etiqueta_valorativa_span | T4: sensacionalismo (J2) | U4: sensacionalismo_span | V4: mind_reading (J2) | W4: mind_reading_span | X4: falta_atribucion (J2) | Y4: falta_atribucion_span | Z4: opinion_como_hecho (J2) | AA4: opinion_como_hecho_span | AB4: direccion | AC4: actor_objetivo | AD4: aux: primera fila de la oración (no editar) | AE4: url_fuente
A5: ART_001 | B5: ART_001_S01 | C5: Infobae Colombia | D5: Política | E5: Noticia dura | F5: Fri, 04 Sep 2026 18:20:11 +0000 | G5: La Alianza Verde salió a responder a las expresiones del senador del Pacto Histórico David Racero contra la representante de su partido Catherine Juvinao durante la discusión del Presupuesto General de la Nación (PGN) 2027 en las comisiones económicas del Congreso de la República. | I5: La colectividad “rechaza contundentemente la violencia política, verbal y simbólica” de la que, según afirma, ha sido víctima la congresista por parte del legislador del Pacto Histórico. | AD5: =IF(AND(COUNTIF($B$5:B5,B5)=1,$B5<>"",$AB5<>""),1,0) | AE5: https://www.infobae.com/colombia/2026/09/04/alianza-verde-critico-a-david-racero-por-llamar-lavaperros-a-catherine-juvinao-durante-la-discusion-del-presupuesto-general-de-la-nacion-violencia-politica-verbal-y-simbolica/
A6: ART_001 | B6: ART_001_S02 | C6: Infobae Colombia | D6: Política | E6: Noticia dura | F6: Fri, 04 Sep 2026 18:20:11 +0000 | G6: La colectividad “rechaza contundentemente la violencia política, verbal y simbólica” de la que, según afirma, ha sido víctima la congresista por parte del legislador del Pacto Histórico. | H6: La Alianza Verde salió a responder a las expresiones del senador del Pacto Histórico David Racero contra la representante de su partido Catherine Juvinao durante la discusión del Presupuesto General de la Nación (PGN) 2027 en las comisiones económicas del Congreso de la República. | AD6: =IF(AND(COUNTIF($B$5:B6,B6)=1,$B6<>"",$AB6<>""),1,0) | AE6: https://www.infobae.com/colombia/2026/09/04/alianza-verde-critico-a-david-racero-por-llamar-lavaperros-a-catherine-juvinao-durante-la-discusion-del-presupuesto-general-de-la-nacion-violencia-politica-verbal-y-simbolica/
A7: ART_002 | B7: ART_002_S01 | C7: Infobae Colombia | D7: Política | E7: Noticia dura | F7: Fri, 04 Sep 2026 02:29:45 +0000 | G7: Ni la Presidencia de la República, ejercida por Abelardo de la Espriella, ni el Ministerio de Defensa, ni la fuerza pública, están autorizadas para ejecutar operaciones aéreas ofensivas en zonas donde se sospeche que hay presencia de niños, niñas y adolescentes reclutados por organizaciones criminales. | AD7: =IF(AND(COUNTIF($B$5:B7,B7)=1,$B7<>"",$AB7<>""),1,0) | AE7: https://www.infobae.com/colombia/2026/09/04/accionante-que-logro-que-un-juzgado-frenara-bombardeos-por-presencia-de-menores-explico-el-alcance-de-su-tutela-se-deben-proteger/
A8: ART_003 | B8: ART_003_S01 | C8: Infobae Colombia | D8: Política | E8: Noticia dura | F8: Sat, 05 Sep 2026 23:40:04 +0000 | G8: Tras el ataque terrorista que perpetró el Ejército de Liberación Nacional (ELN) el 4 de septiembre contra el Cantón Militar El Trapiche, ubicado en Ocaña, Norte de Santander, se llevó a cabo un consejo de seguridad extraordinario para atender la situación de orden público. | I8: El atentado y los combates que se presentaron posteriormente dejaron tres militares asesinados: el capitán Marco David Pirajón Montezuma y los soldados profesionales Joel Alberto Jiménez Jaramillo y Jhon Carlo Marrugo Manjarrez. | AD8: =IF(AND(COUNTIF($B$5:B8,B8)=1,$B8<>"",$AB8<>""),1,0) | AE8: https://www.infobae.com/colombia/2026/09/05/toman-medidas-para-reforzar-la-seguridad-en-ocana-y-norte-de-santander-tras-atentado-del-eln-activaran-la-campana-militar-y-policial-esparta/
A9: ART_003 | B9: ART_003_S02 | C9: Infobae Colombia | D9: Política | E9: Noticia dura | F9: Sat, 05 Sep 2026 23:40:04 +0000 | G9: El atentado y los combates que se presentaron posteriormente dejaron tres militares asesinados: el capitán Marco David Pirajón Montezuma y los soldados profesionales Joel Alberto Jiménez Jaramillo y Jhon Carlo Marrugo Manjarrez. | H9: Tras el ataque terrorista que perpetró el Ejército de Liberación Nacional (ELN) el 4 de septiembre contra el Cantón Militar El Trapiche, ubicado en Ocaña, Norte de Santander, se llevó a cabo un consejo de seguridad extraordinario para atender la situación de orden público. | I9: Ante la gravedad de estos hechos, se establecieron nuevas medidas para reforzar la seguridad y el control territorial en Ocaña y en la región del Catatumbo. | AD9: =IF(AND(COUNTIF($B$5:B9,B9)=1,$B9<>"",$AB9<>""),1,0) | AE9: https://www.infobae.com/colombia/2026/09/05/toman-medidas-para-reforzar-la-seguridad-en-ocana-y-norte-de-santander-tras-atentado-del-eln-activaran-la-campana-militar-y-policial-esparta/
A10: ART_003 | B10: ART_003_S03 | C10: Infobae Colombia | D10: Política | E10: Noticia dura | F10: Sat, 05 Sep 2026 23:40:04 +0000 | G10: Ante la gravedad de estos hechos, se establecieron nuevas medidas para reforzar la seguridad y el control territorial en Ocaña y en la región del Catatumbo. | H10: El atentado y los combates que se presentaron posteriormente dejaron tres militares asesinados: el capitán Marco David Pirajón Montezuma y los soldados profesionales Joel Alberto Jiménez Jaramillo y Jhon Carlo Marrugo Manjarrez. | I10: Durante la reunión, en la que estuvo el Ministerio de Defensa Nacional, la cúpula militar y de la Policía Nacional, y el gobernador de Norte de Santander, William Villamizar Laguado, el Gobierno del presidente Abelardo de la Espriella y las autoridades concertaron hacer una reestructuración y activación de la campaña militar y policial Esparta, con sede en Ocaña, para articular capacidades de las Fuerzas Militares y la Policía Nacional frente a las estructuras criminales que operan en la zona. | AD10: =IF(AND(COUNTIF($B$5:B10,B10)=1,$B10<>"",$AB10<>""),1,0) | AE10: https://www.infobae.com/colombia/2026/09/05/toman-medidas-para-reforzar-la-seguridad-en-ocana-y-norte-de-santander-tras-atentado-del-eln-activaran-la-campana-militar-y-policial-esparta/
A11: ART_003 | B11: ART_003_S04 | C11: Infobae Colombia | D11: Política | E11: Noticia dura | F11: Sat, 05 Sep 2026 23:40:04 +0000 | G11: Durante la reunión, en la que estuvo el Ministerio de Defensa Nacional, la cúpula militar y de la Policía Nacional, y el gobernador de Norte de Santander, William Villamizar Laguado, el Gobierno del presidente Abelardo de la Espriella y las autoridades concertaron hacer una reestructuración y activación de la campaña militar y policial Esparta, con sede en Ocaña, para articular capacidades de las Fuerzas Militares y la Policía Nacional frente a las estructuras criminales que operan en la zona. | H11: Ante la gravedad de estos hechos, se establecieron nuevas medidas para reforzar la seguridad y el control territorial en Ocaña y en la región del Catatumbo. | I11: “Se reforzarán los corredores de movilidad ilegal, las capacidades de inteligencia y la coordinación con la @FiscaliaCol para identificar, capturar y judicializar a los responsables. | AD11: =IF(AND(COUNTIF($B$5:B11,B11)=1,$B11<>"",$AB11<>""),1,0) | AE11: https://www.infobae.com/colombia/2026/09/05/toman-medidas-para-reforzar-la-seguridad-en-ocana-y-norte-de-santander-tras-atentado-del-eln-activaran-la-campana-militar-y-policial-esparta/
A12: ART_003 | B12: ART_003_S05 | C12: Infobae Colombia | D12: Política | E12: Noticia dura | F12: Sat, 05 Sep 2026 23:40:04 +0000 | G12: “Se reforzarán los corredores de movilidad ilegal, las capacidades de inteligencia y la coordinación con la @FiscaliaCol para identificar, capturar y judicializar a los responsables. | H12: Durante la reunión, en la que estuvo el Ministerio de Defensa Nacional, la cúpula militar y de la Policía Nacional, y el gobernador de Norte de Santander, William Villamizar Laguado, el Gobierno del presidente Abelardo de la Espriella y las autoridades concertaron hacer una reestructuración y activación de la campaña militar y policial Esparta, con sede en Ocaña, para articular capacidades de las Fuerzas Militares y la Policía Nacional frente a las estructuras criminales que operan en la zona. | I12: Las @FuerzasMilCol y la @PoliciaColombia mantienen desplegadas todas sus capacidades para proteger a la población y enfrentar con contundencia a quienes atenten contra la seguridad del #Catatumbo”, indicaron las Fuerzas Militares en X. | AD12: =IF(AND(COUNTIF($B$5:B12,B12)=1,$B12<>"",$AB12<>""),1,0) | AE12: https://www.infobae.com/colombia/2026/09/05/toman-medidas-para-reforzar-la-seguridad-en-ocana-y-norte-de-santander-tras-atentado-del-eln-activaran-la-campana-militar-y-policial-esparta/
A13: ART_003 | B13: ART_003_S06 | C13: Infobae Colombia | D13: Política | E13: Noticia dura | F13: Sat, 05 Sep 2026 23:40:04 +0000 | G13: Las @FuerzasMilCol y la @PoliciaColombia mantienen desplegadas todas sus capacidades para proteger a la población y enfrentar con contundencia a quienes atenten contra la seguridad del #Catatumbo”, indicaron las Fuerzas Militares en X. | H13: “Se reforzarán los corredores de movilidad ilegal, las capacidades de inteligencia y la coordinación con la @FiscaliaCol para identificar, capturar y judicializar a los responsables. | AD13: =IF(AND(COUNTIF($B$5:B13,B13)=1,$B13<>"",$AB13<>""),1,0) | AE13: https://www.infobae.com/colombia/2026/09/05/toman-medidas-para-reforzar-la-seguridad-en-ocana-y-norte-de-santander-tras-atentado-del-eln-activaran-la-campana-militar-y-policial-esparta/
A14: ART_004 | B14: ART_004_S01 | C14: Infobae Colombia | D14: Política | E14: Noticia dura | F14: 2026-08-04T18:45:15Z | G14: El director de la Dirección de Impuestos y Aduanas Nacionales (Dian) Carlos Betancourt sostuvo que el aumento de aranceles de Estados Unidos a Colombia, que pasó de 10% a 12,5%, fue una decisión unilateral del gobierno de Donald Trump y no una consecuencia de incumplimientos del Estado colombiano, en un contexto marcado por la guerra comercial con China, la estrategia de Washington para fortalecer sus exportaciones y factores geopolíticos. | AD14: =IF(AND(COUNTIF($B$5:B14,B14)=1,$B14<>"",$AB14<>""),1,0) | AE14: https://www.infobae.com/colombia/2026/08/04/el-director-de-la-dian-atribuyo-a-donald-trump-la-subida-de-aranceles-de-estados-unidos-a-colombia-es-una-decision-unilateral/
A15: ART_005 | B15: ART_005_S01 | C15: Infobae Colombia | D15: Política | E15: Noticia dura | F15: 2026-07-23T23:10:16Z | G15: La administración del presidente Donald Trump confirmó el jueves 23 de julio de 2026 un nuevo paquete de aranceles para las importaciones provenientes de decenas de países, entre ellos Colombia, decisión que fija un gravamen del 12,5% para los productos colombianos que ingresen al mercado estadounidense. | AD15: =IF(AND(COUNTIF($B$5:B15,B15)=1,$B15<>"",$AB15<>""),1,0) | AE15: https://www.infobae.com/colombia/2026/07/23/estados-unidos-endurecio-los-aranceles-para-colombia-exportaciones-pagaran-un-gravamen-del-125/
A16: ART_006 | B16: ART_006_S01 | C16: Infobae Colombia | D16: Política | E16: Noticia dura | F16: 2026-09-07T01:06:46Z | G16: El exministro de Hacienda José Antonio Ocampo se refirió al aval que le dio la Corte Constitucional a la reforma pensional, principalmente, sobre un cambio que considera central: Colpensiones dejaría de competir con el ahorro individual para operar en un esquema complementario. | I16: El exfuncionario dijo que el sistema tendrá costos altos desde 2067, cuando se agoten los recursos de un fondo especial. | AD16: =IF(AND(COUNTIF($B$5:B16,B16)=1,$B16<>"",$AB16<>""),1,0) | AE16: https://www.infobae.com/colombia/2026/09/07/reforma-pensional-confirman-en-que-ano-se-acabara-el-ahorro-de-los-trabajadores-colombianos-y-cuando-colapsara-colpensiones/
A17: ART_006 | B17: ART_006_S02 | C17: Infobae Colombia | D17: Política | E17: Noticia dura | F17: 2026-09-07T01:06:46Z | G17: El exfuncionario dijo que el sistema tendrá costos altos desde 2067, cuando se agoten los recursos de un fondo especial. | H17: El exministro de Hacienda José Antonio Ocampo se refirió al aval que le dio la Corte Constitucional a la reforma pensional, principalmente, sobre un cambio que considera central: Colpensiones dejaría de competir con el ahorro individual para operar en un esquema complementario. | AD17: =IF(AND(COUNTIF($B$5:B17,B17)=1,$B17<>"",$AB17<>""),1,0) | AE17: https://www.infobae.com/colombia/2026/09/07/reforma-pensional-confirman-en-que-ano-se-acabara-el-ahorro-de-los-trabajadores-colombianos-y-cuando-colapsara-colpensiones/
A18: ART_007 | B18: ART_007_S01 | C18: El Tiempo | D18: Política | E18: Noticia dura | F18: 2026-09-04T16:36:43-05:00 | G18: La decisión de la Alianza Verde de declararse como partido independiente al gobierno de Abelardo De La Espriella ha generado polémica. | AD18: =IF(AND(COUNTIF($B$5:B18,B18)=1,$B18<>"",$AB18<>""),1,0) | AE18: https://www.eltiempo.com/politica/partidos-politicos/las-movidas-detras-de-la-declaratoria-de-la-alianza-verde-como-partido-independiente-al-gobierno-de-abelardo-de-la-espriella-3583710
A19: ART_008 | B19: ART_008_S01 | C19: El Tiempo | D19: Política | E19: Noticia dura | F19: 2026-09-04T10:51:14-05:00 | G19: El presidente Abelardo De La Espriella y su cúpula militar confirmaron en Riohacha la muerte de Naín Andrés Pérez Toncel, alias 'Bendito menor', señalado cabecilla de las Autodefensas Conquistadoras de la Sierra Nevada, durante un operativo de la Policía denominado 'Centinela de la patria'. | I19: Según detalló el mandatario, junto al cabecilla de las Acsn también murieron su pareja, Rosa Angélica Tarazona, alias ‘La Bebecita’, y dos escoltas. | AD19: =IF(AND(COUNTIF($B$5:B19,B19)=1,$B19<>"",$AB19<>""),1,0) | AE19: https://www.eltiempo.com/politica/abelardo-de-la-espriella/presidente-abelardo-de-la-espriella-y-su-contundente-frase-tras-la-muerte-de-bendito-menor-este-miserable-ahora-esta-a-buen-recaudo-del-infierno-3583557
A20: ART_008 | B20: ART_008_S02 | C20: El Tiempo | D20: Política | E20: Noticia dura | F20: 2026-09-04T10:51:14-05:00 | G20: Según detalló el mandatario, junto al cabecilla de las Acsn también murieron su pareja, Rosa Angélica Tarazona, alias ‘La Bebecita’, y dos escoltas. | H20: El presidente Abelardo De La Espriella y su cúpula militar confirmaron en Riohacha la muerte de Naín Andrés Pérez Toncel, alias 'Bendito menor', señalado cabecilla de las Autodefensas Conquistadoras de la Sierra Nevada, durante un operativo de la Policía denominado 'Centinela de la patria'. | AD20: =IF(AND(COUNTIF($B$5:B20,B20)=1,$B20<>"",$AB20<>""),1,0) | AE20: https://www.eltiempo.com/politica/abelardo-de-la-espriella/presidente-abelardo-de-la-espriella-y-su-contundente-frase-tras-la-muerte-de-bendito-menor-este-miserable-ahora-esta-a-buen-recaudo-del-infierno-3583557
A21: ART_009 | B21: ART_009_S01 | C21: El Tiempo | D21: Política | E21: Noticia dura | F21: 2026-09-04T07:46:26-05:00 | G21: Washington y Nueva York serán los dos escenarios que marcarán el ritmo de la política exterior del gobierno de Abelardo De La Espriella. | AD21: =IF(AND(COUNTIF($B$5:B21,B21)=1,$B21<>"",$AB21<>""),1,0) | AE21: https://www.eltiempo.com/politica/gobierno/embajadores-ante-ee-uu-y-naciones-unidas-se-preparan-para-asumir-los-destinos-clave-para-la-diplomacia-del-presidente-abelardo-de-la-espriella-3583494
A22: ART_010 | B22: ART_010_S01 | C22: El Tiempo | D22: Política | E22: Noticia dura | F22: 2026-09-04T16:28:46-05:00 | G22: El presidente de Estados Unidos, Donald Trump, afirmó este viernes que México tiene poco que ofrecer a su país más allá de "tamales picantes y tomates", aunque descartó interrumpir la relación comercial bilateral y destacó la buena sintonía que mantiene con la presidenta mexicana, Claudia Sheinbaum. | I22: Trump hizo estas declaraciones en el Despacho Oval al ser consultado por periodistas sobre su amenaza de suspender el comercio con países que mantienen un superávit comercial frente a Estados Unidos. | AD22: =IF(AND(COUNTIF($B$5:B22,B22)=1,$B22<>"",$AB22<>""),1,0) | AE22: https://www.eltiempo.com/mundo/eeuu-y-canada/tamales-picantes-y-tomates-estas-fueron-las-polemicas-declaraciones-de-trump-sobre-la-relacion-comercial-entre-mexico-y-estados-unidos-3583705
A23: ART_010 | B23: ART_010_S02 | C23: El Tiempo | D23: Política | E23: Noticia dura | F23: 2026-09-04T16:28:46-05:00 | G23: Trump hizo estas declaraciones en el Despacho Oval al ser consultado por periodistas sobre su amenaza de suspender el comercio con países que mantienen un superávit comercial frente a Estados Unidos. | H23: El presidente de Estados Unidos, Donald Trump, afirmó este viernes que México tiene poco que ofrecer a su país más allá de "tamales picantes y tomates", aunque descartó interrumpir la relación comercial bilateral y destacó la buena sintonía que mantiene con la presidenta mexicana, Claudia Sheinbaum. | AD23: =IF(AND(COUNTIF($B$5:B23,B23)=1,$B23<>"",$AB23<>""),1,0) | AE23: https://www.eltiempo.com/mundo/eeuu-y-canada/tamales-picantes-y-tomates-estas-fueron-las-polemicas-declaraciones-de-trump-sobre-la-relacion-comercial-entre-mexico-y-estados-unidos-3583705
A24: ART_011 | B24: ART_011_S01 | C24: El Tiempo | D24: Política | E24: Noticia dura | F24: 2026-09-04T16:23:07-05:00 | G24: Después de estar al frente de la Décima Primera Brigada, el brigadier general Óscar del Cristo Díaz Montiel asumió una nueva responsabilidad dentro de la estructura del Ejército. | I24: El oficial fue designado comandante del Comando de Educación y Doctrina (Cedoc), desde donde tendrá a cargo los lineamientos para la formación, instrucción y entrenamiento de los integrantes de la Fuerza. | AD24: =IF(AND(COUNTIF($B$5:B24,B24)=1,$B24<>"",$AB24<>""),1,0) | AE24: https://www.eltiempo.com/justicia/conflicto-y-narcotrafico/general-oscar-diaz-montiel-asume-el-comando-de-educacion-y-doctrina-del-ejercito-3583704
A25: ART_011 | B25: ART_011_S02 | C25: El Tiempo | D25: Política | E25: Noticia dura | F25: 2026-09-04T16:23:07-05:00 | G25: El oficial fue designado comandante del Comando de Educación y Doctrina (Cedoc), desde donde tendrá a cargo los lineamientos para la formación, instrucción y entrenamiento de los integrantes de la Fuerza. | H25: Después de estar al frente de la Décima Primera Brigada, el brigadier general Óscar del Cristo Díaz Montiel asumió una nueva responsabilidad dentro de la estructura del Ejército. | AD25: =IF(AND(COUNTIF($B$5:B25,B25)=1,$B25<>"",$AB25<>""),1,0) | AE25: https://www.eltiempo.com/justicia/conflicto-y-narcotrafico/general-oscar-diaz-montiel-asume-el-comando-de-educacion-y-doctrina-del-ejercito-3583704
A26: ART_012 | B26: ART_012_S01 | C26: El Tiempo | D26: Política | E26: Noticia dura | F26: 2026-09-05T01:05:59-05:00 | G26: Llegar a la edad de pensión no significa automáticamente que una persona vaya a recibir una mesada mensual. | I26: Para pensionarse también debe cumplir determinadas condiciones, que dependen del régimen al que esté afiliado. | AD26: =IF(AND(COUNTIF($B$5:B26,B26)=1,$B26<>"",$AB26<>""),1,0) | AE26: https://www.eltiempo.com/economia/finanzas-personales/que-pasa-con-su-dinero-si-no-alcanza-a-cumplir-las-semanas-necesarias-para-pensionarse-consulte-que-hacer-si-esta-en-porvenir-o-colpensiones-3583613
A27: ART_012 | B27: ART_012_S02 | C27: El Tiempo | D27: Política | E27: Noticia dura | F27: 2026-09-05T01:05:59-05:00 | G27: Para pensionarse también debe cumplir determinadas condiciones, que dependen del régimen al que esté afiliado. | H27: Llegar a la edad de pensión no significa automáticamente que una persona vaya a recibir una mesada mensual. | AD27: =IF(AND(COUNTIF($B$5:B27,B27)=1,$B27<>"",$AB27<>""),1,0) | AE27: https://www.eltiempo.com/economia/finanzas-personales/que-pasa-con-su-dinero-si-no-alcanza-a-cumplir-las-semanas-necesarias-para-pensionarse-consulte-que-hacer-si-esta-en-porvenir-o-colpensiones-3583613
A28: ART_013 | B28: ART_013_S01 | C28: El Tiempo | D28: Política | E28: Opinión-análisis | F28: 2026-05-16T23:45:00-05:00 | G28: Durante más de ocho meses de campaña política hemos visto un proselitismo ampliamente basado en las redes sociales, donde, por un lado, el gobierno de Gustavo Petro y sus bodegas interneteras han trabajado con vigor por su candidato, el comunista Iván Cepeda, y, por el otro, el aspirante ‘outsider’ Abelardo de la Espriella ha cabalgado sobre una poderosa y robusta red de decenas de miles de influenciadores, seguidores y replicadores de su mensaje en las redes sociales. | I28: Si los demás candidatos han quedado rezagados, ha sido en buena medida porque fueron incapaces de usar, con intensidad y eficacia, esas tecnologías. | AD28: =IF(AND(COUNTIF($B$5:B28,B28)=1,$B28<>"",$AB28<>""),1,0) | AE28: https://www.eltiempo.com/opinion/columnistas/una-batalla-sin-partidos-3556318
A29: ART_013 | B29: ART_013_S02 | C29: El Tiempo | D29: Política | E29: Opinión-análisis | F29: 2026-05-16T23:45:00-05:00 | G29: Si los demás candidatos han quedado rezagados, ha sido en buena medida porque fueron incapaces de usar, con intensidad y eficacia, esas tecnologías. | H29: Durante más de ocho meses de campaña política hemos visto un proselitismo ampliamente basado en las redes sociales, donde, por un lado, el gobierno de Gustavo Petro y sus bodegas interneteras han trabajado con vigor por su candidato, el comunista Iván Cepeda, y, por el otro, el aspirante ‘outsider’ Abelardo de la Espriella ha cabalgado sobre una poderosa y robusta red de decenas de miles de influenciadores, seguidores y replicadores de su mensaje en las redes sociales. | I29: Las redes seguirán jugando un papel clave en esta recta final. | AD29: =IF(AND(COUNTIF($B$5:B29,B29)=1,$B29<>"",$AB29<>""),1,0) | AE29: https://www.eltiempo.com/opinion/columnistas/una-batalla-sin-partidos-3556318
A30: ART_013 | B30: ART_013_S03 | C30: El Tiempo | D30: Política | E30: Opinión-análisis | F30: 2026-05-16T23:45:00-05:00 | G30: Las redes seguirán jugando un papel clave en esta recta final. | H30: Si los demás candidatos han quedado rezagados, ha sido en buena medida porque fueron incapaces de usar, con intensidad y eficacia, esas tecnologías. | I30: Pero ahora, a dos semanas de la primera vuelta y cinco de la segunda, la batalla electoral ha aterrizado en la cruda realidad de las calles de ciudades, y de pueblos medianos y pequeños. | AD30: =IF(AND(COUNTIF($B$5:B30,B30)=1,$B30<>"",$AB30<>""),1,0) | AE30: https://www.eltiempo.com/opinion/columnistas/una-batalla-sin-partidos-3556318
A31: ART_013 | B31: ART_013_S04 | C31: El Tiempo | D31: Política | E31: Opinión-análisis | F31: 2026-05-16T23:45:00-05:00 | G31: Pero ahora, a dos semanas de la primera vuelta y cinco de la segunda, la batalla electoral ha aterrizado en la cruda realidad de las calles de ciudades, y de pueblos medianos y pequeños. | H31: Las redes seguirán jugando un papel clave en esta recta final. | I31: La chequera del régimen petrista ha regado cientos de municipios con miles y miles de millones de pesos en contratos de obras y servicios, así como en órdenes de trabajo individuales. | AD31: =IF(AND(COUNTIF($B$5:B31,B31)=1,$B31<>"",$AB31<>""),1,0) | AE31: https://www.eltiempo.com/opinion/columnistas/una-batalla-sin-partidos-3556318
A32: ART_013 | B32: ART_013_S05 | C32: El Tiempo | D32: Política | E32: Opinión-análisis | F32: 2026-05-16T23:45:00-05:00 | G32: La chequera del régimen petrista ha regado cientos de municipios con miles y miles de millones de pesos en contratos de obras y servicios, así como en órdenes de trabajo individuales. | H32: Pero ahora, a dos semanas de la primera vuelta y cinco de la segunda, la batalla electoral ha aterrizado en la cruda realidad de las calles de ciudades, y de pueblos medianos y pequeños. | I32: A ello se suma el apoyo de las bandas armadas que saben que con Cepeda seguirían gozando de la escandalosa impunidad que Petro les ha garantizado. | AD32: =IF(AND(COUNTIF($B$5:B32,B32)=1,$B32<>"",$AB32<>""),1,0) | AE32: https://www.eltiempo.com/opinion/columnistas/una-batalla-sin-partidos-3556318
A33: ART_013 | B33: ART_013_S06 | C33: El Tiempo | D33: Política | E33: Opinión-análisis | F33: 2026-05-16T23:45:00-05:00 | G33: A ello se suma el apoyo de las bandas armadas que saben que con Cepeda seguirían gozando de la escandalosa impunidad que Petro les ha garantizado. | H33: La chequera del régimen petrista ha regado cientos de municipios con miles y miles de millones de pesos en contratos de obras y servicios, así como en órdenes de trabajo individuales. | AD33: =IF(AND(COUNTIF($B$5:B33,B33)=1,$B33<>"",$AB33<>""),1,0) | AE33: https://www.eltiempo.com/opinion/columnistas/una-batalla-sin-partidos-3556318
A34: ART_014 | B34: ART_014_S01 | C34: El Espectador | D34: Política | E34: Noticia dura | F34: Fri, 04 Sep 2026 23:58:00 +0000 | G34: La aerolínea Avianca confirmó que canceló los tiquetes adquiridos por el expresidente Gustavo Petro para su viaje a México debido a que está incluido en la lista OFAC. | I34: El expresidente les respondió. | AD34: =IF(AND(COUNTIF($B$5:B34,B34)=1,$B34<>"",$AB34<>""),1,0) | AE34: https://www.elespectador.com/politica/avianca-confirma-que-cancelo-tiquetes-de-petro-a-mexico-esto-dijo-el-expresidente/
A35: ART_014 | B35: ART_014_S02 | C35: El Espectador | D35: Política | E35: Noticia dura | F35: Fri, 04 Sep 2026 23:58:00 +0000 | G35: El expresidente les respondió. | H35: La aerolínea Avianca confirmó que canceló los tiquetes adquiridos por el expresidente Gustavo Petro para su viaje a México debido a que está incluido en la lista OFAC. | I35: Avianca aseguró que al ser una aerolínea colombiana que opera en territorio estadounidense y “realiza de forma permanente transacciones con su sistema financiero”, se encuentra sujeta a “las regulaciones de sanciones económicas administradas por la Oficina de Control de Activos Extranjeros (OFAC por sus siglas en inglés) del Departamento del Tesoro de los Estados Unidos de América”. | AD35: =IF(AND(COUNTIF($B$5:B35,B35)=1,$B35<>"",$AB35<>""),1,0) | AE35: https://www.elespectador.com/politica/avianca-confirma-que-cancelo-tiquetes-de-petro-a-mexico-esto-dijo-el-expresidente/
A36: ART_014 | B36: ART_014_S03 | C36: El Espectador | D36: Política | E36: Noticia dura | F36: Fri, 04 Sep 2026 23:58:00 +0000 | G36: Avianca aseguró que al ser una aerolínea colombiana que opera en territorio estadounidense y “realiza de forma permanente transacciones con su sistema financiero”, se encuentra sujeta a “las regulaciones de sanciones económicas administradas por la Oficina de Control de Activos Extranjeros (OFAC por sus siglas en inglés) del Departamento del Tesoro de los Estados Unidos de América”. | H36: El expresidente les respondió. | I36: “Dichas regulaciones prohíben a las personas y entidades que, como Avianca, tienen vínculos económicos y financieros con los Estados Unidos de América, realizar transacciones, incluida la prestación de servicios, a favor de cualquier persona cuyos bienes e intereses se encuentren bloqueados por figurar en la Lista de Nacionales Especialmente Designados y Personas Bloqueadas (Lista SDN)”, agregaron. | AD36: =IF(AND(COUNTIF($B$5:B36,B36)=1,$B36<>"",$AB36<>""),1,0) | AE36: https://www.elespectador.com/politica/avianca-confirma-que-cancelo-tiquetes-de-petro-a-mexico-esto-dijo-el-expresidente/
A37: ART_014 | B37: ART_014_S04 | C37: El Espectador | D37: Política | E37: Noticia dura | F37: Fri, 04 Sep 2026 23:58:00 +0000 | G37: “Dichas regulaciones prohíben a las personas y entidades que, como Avianca, tienen vínculos económicos y financieros con los Estados Unidos de América, realizar transacciones, incluida la prestación de servicios, a favor de cualquier persona cuyos bienes e intereses se encuentren bloqueados por figurar en la Lista de Nacionales Especialmente Designados y Personas Bloqueadas (Lista SDN)”, agregaron. | H37: Avianca aseguró que al ser una aerolínea colombiana que opera en territorio estadounidense y “realiza de forma permanente transacciones con su sistema financiero”, se encuentra sujeta a “las regulaciones de sanciones económicas administradas por la Oficina de Control de Activos Extranjeros (OFAC por sus siglas en inglés) del Departamento del Tesoro de los Estados Unidos de América”. | I37: Por esta razón, la aerolínea canceló las reservas que fueron hechas por el expresidente Gustavo Petro y reembolsó la totalidad del valor que había sido pagado. | AD37: =IF(AND(COUNTIF($B$5:B37,B37)=1,$B37<>"",$AB37<>""),1,0) | AE37: https://www.elespectador.com/politica/avianca-confirma-que-cancelo-tiquetes-de-petro-a-mexico-esto-dijo-el-expresidente/
A38: ART_014 | B38: ART_014_S05 | C38: El Espectador | D38: Política | E38: Noticia dura | F38: Fri, 04 Sep 2026 23:58:00 +0000 | G38: Por esta razón, la aerolínea canceló las reservas que fueron hechas por el expresidente Gustavo Petro y reembolsó la totalidad del valor que había sido pagado. | H38: “Dichas regulaciones prohíben a las personas y entidades que, como Avianca, tienen vínculos económicos y financieros con los Estados Unidos de América, realizar transacciones, incluida la prestación de servicios, a favor de cualquier persona cuyos bienes e intereses se encuentren bloqueados por figurar en la Lista de Nacionales Especialmente Designados y Personas Bloqueadas (Lista SDN)”, agregaron. | AD38: =IF(AND(COUNTIF($B$5:B38,B38)=1,$B38<>"",$AB38<>""),1,0) | AE38: https://www.elespectador.com/politica/avianca-confirma-que-cancelo-tiquetes-de-petro-a-mexico-esto-dijo-el-expresidente/
A39: ART_015 | B39: ART_015_S01 | C39: El Espectador | D39: Política | E39: Noticia dura | F39: Sun, 06 Sep 2026 00:22:17 +0000 | G39: El general (r) Jorge Eduardo Mora, junto con la cúpula militar y de Policía, anunció un nuevo paquete de medidas para reforzar la seguridad y el control territorial en Ocaña y el Catatumbo, tras el ataque terrorista perpetrado por el Eln la noche del pasado 4 de septiembre contra el Cantón Militar El Trapiche, que dejó tres militares muertos. | I39: Las decisiones se adoptaron en un consejo de seguridad en el que participaron el gobernador de Norte de Santander y altos mandos militares y policiales de la región. | AD39: =IF(AND(COUNTIF($B$5:B39,B39)=1,$B39<>"",$AB39<>""),1,0) | AE39: https://www.elespectador.com/judicial/mindefensa-anuncia-nuevas-medidas-de-seguridad-tras-ataque-con-drones-del-eln-en-ocana/
A40: ART_015 | B40: ART_015_S02 | C40: El Espectador | D40: Política | E40: Noticia dura | F40: Sun, 06 Sep 2026 00:22:17 +0000 | G40: Las decisiones se adoptaron en un consejo de seguridad en el que participaron el gobernador de Norte de Santander y altos mandos militares y policiales de la región. | H40: El general (r) Jorge Eduardo Mora, junto con la cúpula militar y de Policía, anunció un nuevo paquete de medidas para reforzar la seguridad y el control territorial en Ocaña y el Catatumbo, tras el ataque terrorista perpetrado por el Eln la noche del pasado 4 de septiembre contra el Cantón Militar El Trapiche, que dejó tres militares muertos. | I40: Como primera medida, se ordenó la reestructuración, reorganización y activación de la campaña militar y policial “Esparta”, que tendrá su sede en Ocaña y buscará articular las capacidades de las Fuerzas Militares y de la Policía Nacional para enfrentar a las estructuras criminales que operan en la zona. | AD40: =IF(AND(COUNTIF($B$5:B40,B40)=1,$B40<>"",$AB40<>""),1,0) | AE40: https://www.elespectador.com/judicial/mindefensa-anuncia-nuevas-medidas-de-seguridad-tras-ataque-con-drones-del-eln-en-ocana/
A41: ART_015 | B41: ART_015_S03 | C41: El Espectador | D41: Política | E41: Noticia dura | F41: Sun, 06 Sep 2026 00:22:17 +0000 | G41: Como primera medida, se ordenó la reestructuración, reorganización y activación de la campaña militar y policial “Esparta”, que tendrá su sede en Ocaña y buscará articular las capacidades de las Fuerzas Militares y de la Policía Nacional para enfrentar a las estructuras criminales que operan en la zona. | H41: Las decisiones se adoptaron en un consejo de seguridad en el que participaron el gobernador de Norte de Santander y altos mandos militares y policiales de la región. | I41: También se dispuso fortalecer el bloqueo y la contención de los corredores utilizados por los grupos armados ilegales para movilizar hombres, armas, explosivos y recursos ilícitos entre el sur del Cesar y Ocaña. | AD41: =IF(AND(COUNTIF($B$5:B41,B41)=1,$B41<>"",$AB41<>""),1,0) | AE41: https://www.elespectador.com/judicial/mindefensa-anuncia-nuevas-medidas-de-seguridad-tras-ataque-con-drones-del-eln-en-ocana/
...
