Workbook

Sheet Grid de recoleccion
A1: Grid de recolección — 500 oraciones (5 medios x 5 temas)
A2: Celdas en AMARILLO son las que se editan: objetivos ya propuestos (ajustables), artículos recolectados y estado. La columna 'Oraciones anotadas (real)' YA NO se llena a mano: se calcula sola contando lo que hay en la hoja 'Corpus - oraciones'.
A4: Medio | B4: Tema | C4: Objetivo oraciones (dura) | D4: Objetivo oraciones (opinión/análisis) | E4: Objetivo total | F4: Artículos recolectados (dura) | G4: Artículos recolectados (opinión) | H4: Oraciones anotadas (real) | I4: % avance | J4: Estado | K4: Notas
A5: Infobae Colombia | B5: Transición de gobierno y relación con la oposición | C5: 20 | D5: 0 | E5: =C5+D5 | F5: 3 | G5: 0 | H5: =SUMIFS('Corpus - oraciones'!$AF$3:$AF$600,'Corpus - oraciones'!$C$3:$C$600,A5,'Corpus - oraciones'!$D$3:$D$600,B5) | I5: =IFERROR(H5/E5,0) | J5: Pendiente | K5: Redistribuido 2026-09-05: sin opinión propia de Colombia (ver aviso_legal en medios.yaml); objetivo movido íntegro a dura.
A6: Infobae Colombia | B6: Respuesta a la emergencia del terremoto | C6: 20 | D6: 0 | E6: =C6+D6 | F6: 3 | G6: 0 | H6: =SUMIFS('Corpus - oraciones'!$AF$3:$AF$600,'Corpus - oraciones'!$C$3:$C$600,A6,'Corpus - oraciones'!$D$3:$D$600,B6) | I6: =IFERROR(H6/E6,0) | J6: Pendiente | K6: Redistribuido 2026-09-05: sin opinión propia de Colombia (ver aviso_legal en medios.yaml); objetivo movido íntegro a dura.
A7: Infobae Colombia | B7: Relación con Estados Unidos | C7: 20 | D7: 0 | E7: =C7+D7 | F7: 4 | G7: 0 | H7: =SUMIFS('Corpus - oraciones'!$AF$3:$AF$600,'Corpus - oraciones'!$C$3:$C$600,A7,'Corpus - oraciones'!$D$3:$D$600,B7) | I7: =IFERROR(H7/E7,0) | J7: Pendiente | K7: Redistribuido 2026-09-05: sin opinión propia de Colombia (ver aviso_legal en medios.yaml); objetivo movido íntegro a dura.
A8: Infobae Colombia | B8: Reformas sociales en disputa (pensional/tributaria) | C8: 20 | D8: 0 | E8: =C8+D8 | F8: 3 | G8: 0 | H8: =SUMIFS('Corpus - oraciones'!$AF$3:$AF$600,'Corpus - oraciones'!$C$3:$C$600,A8,'Corpus - oraciones'!$D$3:$D$600,B8) | I8: =IFERROR(H8/E8,0) | J8: Pendiente | K8: Redistribuido 2026-09-05: sin opinión propia de Colombia (ver aviso_legal en medios.yaml); objetivo movido íntegro a dura.
A9: Infobae Colombia | B9: Seguridad y orden público | C9: 20 | D9: 0 | E9: =C9+D9 | F9: 3 | G9: 0 | H9: =SUMIFS('Corpus - oraciones'!$AF$3:$AF$600,'Corpus - oraciones'!$C$3:$C$600,A9,'Corpus - oraciones'!$D$3:$D$600,B9) | I9: =IFERROR(H9/E9,0) | J9: Pendiente | K9: Redistribuido 2026-09-05: sin opinión propia de Colombia (ver aviso_legal en medios.yaml); objetivo movido íntegro a dura.
A10: El Tiempo | B10: Transición de gobierno y relación con la oposición | C10: 14 | D10: 6 | E10: =C10+D10 | F10: 2 | G10: 1 | H10: =SUMIFS('Corpus - oraciones'!$AF$3:$AF$600,'Corpus - oraciones'!$C$3:$C$600,A10,'Corpus - oraciones'!$D$3:$D$600,B10) | I10: =IFERROR(H10/E10,0) | J10: Pendiente
A11: El Tiempo | B11: Respuesta a la emergencia del terremoto | C11: 14 | D11: 6 | E11: =C11+D11 | F11: 3 | G11: 1 | H11: =SUMIFS('Corpus - oraciones'!$AF$3:$AF$600,'Corpus - oraciones'!$C$3:$C$600,A11,'Corpus - oraciones'!$D$3:$D$600,B11) | I11: =IFERROR(H11/E11,0) | J11: Pendiente
A12: El Tiempo | B12: Relación con Estados Unidos | C12: 20 | D12: 0 | E12: =C12+D12 | F12: 3 | G12: 0 | H12: =SUMIFS('Corpus - oraciones'!$AF$3:$AF$600,'Corpus - oraciones'!$C$3:$C$600,A12,'Corpus - oraciones'!$D$3:$D$600,B12) | I12: =IFERROR(H12/E12,0) | J12: Pendiente | K12: Redistribuido 2026-09-05: no se encontró columna de opinión propia sobre Estados Unidos en circulación actual (se probaron ~15 columnas de opinión de El Tiempo -- política exterior, editoriales -- ninguna calificó tras verificar con clasificar_tema()); objetivo movido íntegro a dura, igual que Infobae/El Espectador-Seguridad.
A13: El Tiempo | B13: Reformas sociales en disputa (pensional/tributaria) | C13: 14 | D13: 6 | E13: =C13+D13 | F13: 2 | G13: 1 | H13: =SUMIFS('Corpus - oraciones'!$AF$3:$AF$600,'Corpus - oraciones'!$C$3:$C$600,A13,'Corpus - oraciones'!$D$3:$D$600,B13) | I13: =IFERROR(H13/E13,0) | J13: Pendiente
A14: El Tiempo | B14: Seguridad y orden público | C14: 14 | D14: 6 | E14: =C14+D14 | F14: 2 | G14: 1 | H14: =SUMIFS('Corpus - oraciones'!$AF$3:$AF$600,'Corpus - oraciones'!$C$3:$C$600,A14,'Corpus - oraciones'!$D$3:$D$600,B14) | I14: =IFERROR(H14/E14,0) | J14: Pendiente
A15: El Espectador | B15: Transición de gobierno y relación con la oposición | C15: 6 | D15: 14 | E15: =C15+D15 | F15: 1 | G15: 1 | H15: =SUMIFS('Corpus - oraciones'!$AF$3:$AF$600,'Corpus - oraciones'!$C$3:$C$600,A15,'Corpus - oraciones'!$D$3:$D$600,B15) | I15: =IFERROR(H15/E15,0) | J15: Pendiente
A16: El Espectador | B16: Respuesta a la emergencia del terremoto | C16: 6 | D16: 14 | E16: =C16+D16 | F16: 1 | G16: 1 | H16: =SUMIFS('Corpus - oraciones'!$AF$3:$AF$600,'Corpus - oraciones'!$C$3:$C$600,A16,'Corpus - oraciones'!$D$3:$D$600,B16) | I16: =IFERROR(H16/E16,0) | J16: Pendiente
A17: El Espectador | B17: Relación con Estados Unidos | C17: 6 | D17: 14 | E17: =C17+D17 | F17: 1 | G17: 1 | H17: =SUMIFS('Corpus - oraciones'!$AF$3:$AF$600,'Corpus - oraciones'!$C$3:$C$600,A17,'Corpus - oraciones'!$D$3:$D$600,B17) | I17: =IFERROR(H17/E17,0) | J17: Pendiente
A18: El Espectador | B18: Reformas sociales en disputa (pensional/tributaria) | C18: 6 | D18: 14 | E18: =C18+D18 | F18: 1 | G18: 1 | H18: =SUMIFS('Corpus - oraciones'!$AF$3:$AF$600,'Corpus - oraciones'!$C$3:$C$600,A18,'Corpus - oraciones'!$D$3:$D$600,B18) | I18: =IFERROR(H18/E18,0) | J18: Pendiente
A19: El Espectador | B19: Seguridad y orden público | C19: 20 | D19: 0 | E19: =C19+D19 | F19: 3 | G19: 0 | H19: =SUMIFS('Corpus - oraciones'!$AF$3:$AF$600,'Corpus - oraciones'!$C$3:$C$600,A19,'Corpus - oraciones'!$D$3:$D$600,B19) | I19: =IFERROR(H19/E19,0) | J19: Pendiente | K19: Redistribuido 2026-09-05: sin opinión sobre seguridad disponible tras 2 intentos; objetivo movido íntegro a dura.
A20: La Silla Vacía | B20: Transición de gobierno y relación con la oposición | C20: 8 | D20: 12 | E20: =C20+D20 | F20: 1 | G20: 2 | H20: =SUMIFS('Corpus - oraciones'!$AF$3:$AF$600,'Corpus - oraciones'!$C$3:$C$600,A20,'Corpus - oraciones'!$D$3:$D$600,B20) | I20: =IFERROR(H20/E20,0) | J20: Pendiente
A21: La Silla Vacía | B21: Respuesta a la emergencia del terremoto | C21: 8 | D21: 12 | E21: =C21+D21 | F21: 1 | G21: 2 | H21: =SUMIFS('Corpus - oraciones'!$AF$3:$AF$600,'Corpus - oraciones'!$C$3:$C$600,A21,'Corpus - oraciones'!$D$3:$D$600,B21) | I21: =IFERROR(H21/E21,0) | J21: Pendiente
A22: La Silla Vacía | B22: Relación con Estados Unidos | C22: 8 | D22: 12 | E22: =C22+D22 | F22: 1 | G22: 3 | H22: =SUMIFS('Corpus - oraciones'!$AF$3:$AF$600,'Corpus - oraciones'!$C$3:$C$600,A22,'Corpus - oraciones'!$D$3:$D$600,B22) | I22: =IFERROR(H22/E22,0) | J22: Pendiente
A23: La Silla Vacía | B23: Reformas sociales en disputa (pensional/tributaria) | C23: 8 | D23: 12 | E23: =C23+D23 | F23: 1 | G23: 3 | H23: =SUMIFS('Corpus - oraciones'!$AF$3:$AF$600,'Corpus - oraciones'!$C$3:$C$600,A23,'Corpus - oraciones'!$D$3:$D$600,B23) | I23: =IFERROR(H23/E23,0) | J23: Pendiente
A24: La Silla Vacía | B24: Seguridad y orden público | C24: 8 | D24: 12 | E24: =C24+D24 | F24: 1 | G24: 3 | H24: =SUMIFS('Corpus - oraciones'!$AF$3:$AF$600,'Corpus - oraciones'!$C$3:$C$600,A24,'Corpus - oraciones'!$D$3:$D$600,B24) | I24: =IFERROR(H24/E24,0) | J24: Pendiente
A25: Semana | B25: Transición de gobierno y relación con la oposición | C25: 10 | D25: 10 | E25: =C25+D25 | F25: 1 | G25: 1 | H25: =SUMIFS('Corpus - oraciones'!$AF$3:$AF$600,'Corpus - oraciones'!$C$3:$C$600,A25,'Corpus - oraciones'!$D$3:$D$600,B25) | I25: =IFERROR(H25/E25,0) | J25: Pendiente
A26: Semana | B26: Respuesta a la emergencia del terremoto | C26: 10 | D26: 10 | E26: =C26+D26 | F26: 1 | G26: 1 | H26: =SUMIFS('Corpus - oraciones'!$AF$3:$AF$600,'Corpus - oraciones'!$C$3:$C$600,A26,'Corpus - oraciones'!$D$3:$D$600,B26) | I26: =IFERROR(H26/E26,0) | J26: Pendiente
A27: Semana | B27: Relación con Estados Unidos | C27: 10 | D27: 10 | E27: =C27+D27 | F27: 1 | G27: 1 | H27: =SUMIFS('Corpus - oraciones'!$AF$3:$AF$600,'Corpus - oraciones'!$C$3:$C$600,A27,'Corpus - oraciones'!$D$3:$D$600,B27) | I27: =IFERROR(H27/E27,0) | J27: Pendiente
A28: Semana | B28: Reformas sociales en disputa (pensional/tributaria) | C28: 10 | D28: 10 | E28: =C28+D28 | F28: 1 | G28: 1 | H28: =SUMIFS('Corpus - oraciones'!$AF$3:$AF$600,'Corpus - oraciones'!$C$3:$C$600,A28,'Corpus - oraciones'!$D$3:$D$600,B28) | I28: =IFERROR(H28/E28,0) | J28: Pendiente
A29: Semana | B29: Seguridad y orden público | C29: 10 | D29: 10 | E29: =C29+D29 | F29: 1 | G29: 1 | H29: =SUMIFS('Corpus - oraciones'!$AF$3:$AF$600,'Corpus - oraciones'!$C$3:$C$600,A29,'Corpus - oraciones'!$D$3:$D$600,B29) | I29: =IFERROR(H29/E29,0) | J29: Pendiente
A30: TOTAL | C30: =SUM(C5:C29) | D30: =SUM(D5:D29) | E30: =SUM(E5:E29) | H30: =SUM(H5:H29) | I30: =IFERROR(H30/E30,0)

Sheet Resumen
A1: Resumen por medio y por tema
A3: Por medio
A4: Medio | B4: Objetivo total | C4: Oraciones anotadas | D4: % avance
A5: Infobae Colombia | B5: =SUMIF('Grid de recoleccion'!A:A,A5,'Grid de recoleccion'!E:E) | C5: =SUMIF('Grid de recoleccion'!A:A,A5,'Grid de recoleccion'!H:H) | D5: =IFERROR(C5/B5,0)
A6: El Tiempo | B6: =SUMIF('Grid de recoleccion'!A:A,A6,'Grid de recoleccion'!E:E) | C6: =SUMIF('Grid de recoleccion'!A:A,A6,'Grid de recoleccion'!H:H) | D6: =IFERROR(C6/B6,0)
A7: El Espectador | B7: =SUMIF('Grid de recoleccion'!A:A,A7,'Grid de recoleccion'!E:E) | C7: =SUMIF('Grid de recoleccion'!A:A,A7,'Grid de recoleccion'!H:H) | D7: =IFERROR(C7/B7,0)
A8: La Silla Vacía | B8: =SUMIF('Grid de recoleccion'!A:A,A8,'Grid de recoleccion'!E:E) | C8: =SUMIF('Grid de recoleccion'!A:A,A8,'Grid de recoleccion'!H:H) | D8: =IFERROR(C8/B8,0)
A9: Semana | B9: =SUMIF('Grid de recoleccion'!A:A,A9,'Grid de recoleccion'!E:E) | C9: =SUMIF('Grid de recoleccion'!A:A,A9,'Grid de recoleccion'!H:H) | D9: =IFERROR(C9/B9,0)
A10: TOTAL | B10: =SUM(B5:B9) | C10: =SUM(C5:C9) | D10: =IFERROR(C10/B10,0)
A13: Por tema
A14: Tema | B14: Objetivo total | C14: Oraciones anotadas | D14: % avance
A15: Transición de gobierno y relación con la oposición | B15: =SUMIF('Grid de recoleccion'!B:B,A15,'Grid de recoleccion'!E:E) | C15: =SUMIF('Grid de recoleccion'!B:B,A15,'Grid de recoleccion'!H:H) | D15: =IFERROR(C15/B15,0)
A16: Respuesta a la emergencia del terremoto | B16: =SUMIF('Grid de recoleccion'!B:B,A16,'Grid de recoleccion'!E:E) | C16: =SUMIF('Grid de recoleccion'!B:B,A16,'Grid de recoleccion'!H:H) | D16: =IFERROR(C16/B16,0)
A17: Relación con Estados Unidos | B17: =SUMIF('Grid de recoleccion'!B:B,A17,'Grid de recoleccion'!E:E) | C17: =SUMIF('Grid de recoleccion'!B:B,A17,'Grid de recoleccion'!H:H) | D17: =IFERROR(C17/B17,0)
A18: Reformas sociales en disputa (pensional/tributaria) | B18: =SUMIF('Grid de recoleccion'!B:B,A18,'Grid de recoleccion'!E:E) | C18: =SUMIF('Grid de recoleccion'!B:B,A18,'Grid de recoleccion'!H:H) | D18: =IFERROR(C18/B18,0)
A19: Seguridad y orden público | B19: =SUMIF('Grid de recoleccion'!B:B,A19,'Grid de recoleccion'!E:E) | C19: =SUMIF('Grid de recoleccion'!B:B,A19,'Grid de recoleccion'!H:H) | D19: =IFERROR(C19/B19,0)
A20: TOTAL | B20: =SUM(B15:B19) | C20: =SUM(C15:C19) | D20: =IFERROR(C20/B20,0)

Sheet Leyenda
A1: Cómo usar este archivo
A3: Objetivo oraciones (dura) / (opinión) | B3: Editable (amarillo). Ya vienen propuestos según la fortaleza de cada medio — ajústalos si el avance real muestra que un medio/tema rinde distinto a lo esperado.
A4: Objetivo total | B4: Se calcula solo (dura + opinión). No editar.
A5: Artículos recolectados (dura/opinión) | B5: Editable. Cuenta cuántos artículos de cada género llevas recolectados para esa celda.
A6: Oraciones anotadas (real) | B6: Editable. Actualízalo a medida que el profesional anota — es lo que alimenta el % de avance.
A7: % avance | B7: Se calcula solo (oraciones anotadas / objetivo total). Rojo = arrancando, amarillo = a mitad, verde = completo.
A8: Estado | B8: Editable, selecciona de la lista desplegable: Pendiente / En progreso / Completo.
A9: Notas | B9: Editable, libre — por ejemplo "El Espectador: solo se consiguieron 4 de 6 artículos de opinión, faltan 2".
A10: Hoja Resumen | B10: Se calcula sola a partir de la hoja principal — no editar directamente, solo lectura.
A12: Ejemplo de fila ya en progreso (referencia, no editar aquí):
A13: Infobae — Seguridad y orden público | B13: Objetivo 20 (14 dura + 6 opinión); llevan 3 artículos dura + 1 opinión recolectados, 17 oraciones ya anotadas → 85% avance, Estado: En progreso.
A15: Hoja 'Corpus - oraciones' | B15: Aquí van las 500 oraciones reales con su texto y su anotación. Las 3 primeras filas (en gris, cursiva) son el ejemplo de referencia -- una fila por oración, no se editan ni se cuentan (fila 5 = ejemplo con hallazgo léxico Y discursivo a la vez, fila 6 = ejemplo con hallazgo solo discursivo, fila 7 = ejemplo neutral). IMPORTANTE: toda oración revisada recibe exactamente una fila, incluso si todas las categorías quedan en FALSE -- las oraciones neutras son tan necesarias como las sesgadas, no se omiten. Esquema completo (Tabla 1 de esquemas_anotacion.xlsx): 5 categorías léxicas J1 (verbo_factivo, verbo_asertivo, palabra_subjetiva, hedge, etiqueta_valorativa) + 4 discursivas J2 (sensacionalismo, mind_reading, falta_atribucion, opinion_como_hecho), cada una con su propia columna de span al lado (se llena solo si esa categoría quedó en TRUE). direccion/actor_objetivo aplican sobre cualquiera de los dos niveles (actor_objetivo es obligatorio si direccion != neutral). intensidad_lexica se llena solo si algún J1 quedó TRUE; camuflaje_epistemico solo si algún J2 quedó TRUE -- ambas en escala 1-5 (ver manual). medio/tema/género/direccion/las 9 categorías booleanas tienen lista desplegable. La columna 'aux' alimenta automáticamente el avance en la hoja principal -- no se toca.

Sheet Corpus - oraciones
A1: Corpus real — una fila por oración (esquema completo: 9 categorías léxico/discursivo)
A2: Aquí van las 500 oraciones reales, su texto, y su anotación (esquema completo: J1 léxico + J2 discursivo, 9 categorías, cada una con su span). Celdas amarillas = editables. La columna AF es auxiliar, no se edita -- alimenta el conteo automático de la hoja 'Grid de recoleccion'.
A4: articulo_id | B4: oracion_id | C4: medio | D4: tema | E4: género (dura/opinión) | F4: fecha_ publicación | G4: oracion_texto | H4: oracion_anterior | I4: oracion_siguiente | J4: verbo_factivo (J1) | K4: verbo_factivo_span | L4: verbo_asertivo (J1) | M4: verbo_asertivo_span | N4: palabra_subjetiva (J1) | O4: palabra_subjetiva_span | P4: hedge (J1) | Q4: hedge_span | R4: etiqueta_valorativa (J1) | S4: etiqueta_valorativa_span | T4: sensacionalismo (J2) | U4: sensacionalismo_span | V4: mind_reading (J2) | W4: mind_reading_span | X4: falta_atribucion (J2) | Y4: falta_atribucion_span | Z4: opinion_como_hecho (J2) | AA4: opinion_como_hecho_span | AB4: direccion | AC4: actor_objetivo | AD4: intensidad_lexica (1-5, si J1) | AE4: camuflaje_epistemico (1-5, si J2) | AF4: aux: primera fila de la oración (no editar) | AG4: url_fuente
A5: ART_0231 | B5: ART_0231_S07 | C5: El Tiempo | D5: Transición de gobierno y relación con la oposición | E5: Noticia dura | F5: 2026-08-20 | G5: El Gobierno impuso la polémica reforma tributaria pese a las advertencias de los gremios, sabiendo que afectaría directamente a la clase media. | H5: El anuncio se dio durante la rueda de prensa de la tarde. | I5: El Ministerio de Hacienda no respondió a las solicitudes de entrevista. | J5: FALSE | L5: FALSE | N5: FALSE | P5: FALSE | R5: TRUE | S5: polémica | T5: FALSE | V5: TRUE | W5: sabiendo que afectaría directamente a la clase media | X5: FALSE | Z5: FALSE | AB5: perjudica | AC5: Gobierno nacional | AD5: 3 | AE5: 4 | AF5: =IF(COUNTIF($B$5:B5,B5)=1,1,0)
A6: ART_0198 | B6: ART_0198_S02 | C6: El Espectador | D6: Reformas sociales en disputa (pensional/tributaria) | E6: Opinión-análisis | F6: 2026-07-10 | G6: El plan pensional fracasará antes de que termine el año. | H6: El columnista abrió su texto recordando las promesas de campaña. | I6: Nadie en el Gobierno ha salido a desmentirlo. | J6: FALSE | L6: FALSE | N6: FALSE | P6: FALSE | R6: FALSE | T6: FALSE | V6: FALSE | X6: FALSE | Z6: TRUE | AA6: El plan pensional fracasará antes de que termine el año | AB6: perjudica | AC6: Gobierno nacional / reforma pensional | AE6: 3 | AF6: =IF(COUNTIF($B$5:B6,B6)=1,1,0)
A7: ART_0245 | B7: ART_0245_S03 | C7: El Tiempo | D7: Transición de gobierno y relación con la oposición | E7: Noticia dura | F7: 2026-08-20 | G7: El Banco de la República publicará el informe de inflación el próximo martes. | H7: La medida se conoció durante la sesión ordinaria. | I7: Analistas esperan el dato con atención. | J7: FALSE | L7: FALSE | N7: FALSE | P7: FALSE | R7: FALSE | T7: FALSE | V7: FALSE | X7: FALSE | Z7: FALSE | AB7: neutral | AF7: =IF(COUNTIF($B$5:B7,B7)=1,1,0)
A8: ART_001 | B8: ART_001_S01 | C8: Infobae Colombia | D8: Seguridad y orden público | E8: Noticia dura | F8: Fri, 04 Sep 2026 21:14:49 +0000 | G8: El Instituto Nacional de Medicina Legal y Ciencias Forenses comunicó oficialmente que identificó a 20 de los 24 cuerpos que recibió tras las acciones militares que desarrollaron de manera conjunta las fuerzas del orden en la vereda Lagos del Dorado, en el municipio de Miraflores, Guaviare, a través de la Operación Azarías en contra de los grupos armados que tienen presencia en el arco amazónico. | I8: La entidad aseguró que los cuerpos ingresaron el 1 de septiembre de 2026. | AF8: =IF(COUNTIF($B$5:B8,B8)=1,1,0) | AG8: https://www.infobae.com/colombia/2026/09/04/medicina-legal-confirmo-los-resultados-de-la-operacion-azarias-en-guaviare-en-la-que-murieron-23-disidentes-dos-eran-menores-de-edad/
A9: ART_001 | B9: ART_001_S02 | C9: Infobae Colombia | D9: Seguridad y orden público | E9: Noticia dura | F9: Fri, 04 Sep 2026 21:14:49 +0000 | G9: La entidad aseguró que los cuerpos ingresaron el 1 de septiembre de 2026. | H9: El Instituto Nacional de Medicina Legal y Ciencias Forenses comunicó oficialmente que identificó a 20 de los 24 cuerpos que recibió tras las acciones militares que desarrollaron de manera conjunta las fuerzas del orden en la vereda Lagos del Dorado, en el municipio de Miraflores, Guaviare, a través de la Operación Azarías en contra de los grupos armados que tienen presencia en el arco amazónico. | I9: Del total de 24 cuerpos inertes recibidos, cuatro permanecen en abordaje forense debido a las condiciones en que fueron entregados. | AF9: =IF(COUNTIF($B$5:B9,B9)=1,1,0) | AG9: https://www.infobae.com/colombia/2026/09/04/medicina-legal-confirmo-los-resultados-de-la-operacion-azarias-en-guaviare-en-la-que-murieron-23-disidentes-dos-eran-menores-de-edad/
A10: ART_001 | B10: ART_001_S03 | C10: Infobae Colombia | D10: Seguridad y orden público | E10: Noticia dura | F10: Fri, 04 Sep 2026 21:14:49 +0000 | G10: Del total de 24 cuerpos inertes recibidos, cuatro permanecen en abordaje forense debido a las condiciones en que fueron entregados. | H10: La entidad aseguró que los cuerpos ingresaron el 1 de septiembre de 2026. | I10: Medicina Legal ratificó que, además, entre las 20 personas identificadas hay ocho mujeres y 12 hombres, de acuerdo con el balance oficial que se divulgó este 4 de septiembre. | AF10: =IF(COUNTIF($B$5:B10,B10)=1,1,0) | AG10: https://www.infobae.com/colombia/2026/09/04/medicina-legal-confirmo-los-resultados-de-la-operacion-azarias-en-guaviare-en-la-que-murieron-23-disidentes-dos-eran-menores-de-edad/
A11: ART_001 | B11: ART_001_S04 | C11: Infobae Colombia | D11: Seguridad y orden público | E11: Noticia dura | F11: Fri, 04 Sep 2026 21:14:49 +0000 | G11: Medicina Legal ratificó que, además, entre las 20 personas identificadas hay ocho mujeres y 12 hombres, de acuerdo con el balance oficial que se divulgó este 4 de septiembre. | H11: Del total de 24 cuerpos inertes recibidos, cuatro permanecen en abordaje forense debido a las condiciones en que fueron entregados. | I11: Frente a la polémica por la presunta presencia de menores en el área en la que se desarrolló la ofensiva, el Instituto precisó que dos de las personas abatidas ya identificadas son menores de edad. | AF11: =IF(COUNTIF($B$5:B11,B11)=1,1,0) | AG11: https://www.infobae.com/colombia/2026/09/04/medicina-legal-confirmo-los-resultados-de-la-operacion-azarias-en-guaviare-en-la-que-murieron-23-disidentes-dos-eran-menores-de-edad/
A12: ART_001 | B12: ART_001_S05 | C12: Infobae Colombia | D12: Seguridad y orden público | E12: Noticia dura | F12: Fri, 04 Sep 2026 21:14:49 +0000 | G12: Frente a la polémica por la presunta presencia de menores en el área en la que se desarrolló la ofensiva, el Instituto precisó que dos de las personas abatidas ya identificadas son menores de edad. | H12: Medicina Legal ratificó que, además, entre las 20 personas identificadas hay ocho mujeres y 12 hombres, de acuerdo con el balance oficial que se divulgó este 4 de septiembre. | I12: El comunicado no detalló sus identidades, edades ni las circunstancias en las que murieron. | AF12: =IF(COUNTIF($B$5:B12,B12)=1,1,0) | AG12: https://www.infobae.com/colombia/2026/09/04/medicina-legal-confirmo-los-resultados-de-la-operacion-azarias-en-guaviare-en-la-que-murieron-23-disidentes-dos-eran-menores-de-edad/
A13: ART_001 | B13: ART_001_S06 | C13: Infobae Colombia | D13: Seguridad y orden público | E13: Noticia dura | F13: Fri, 04 Sep 2026 21:14:49 +0000 | G13: El comunicado no detalló sus identidades, edades ni las circunstancias en las que murieron. | H13: Frente a la polémica por la presunta presencia de menores en el área en la que se desarrolló la ofensiva, el Instituto precisó que dos de las personas abatidas ya identificadas son menores de edad. | I13: En cuanto a los procedimientos sobre los cuatro cuerpos pendientes, las identificaciones continuarán pese a las dificultades que presentan los cadáveres. | AF13: =IF(COUNTIF($B$5:B13,B13)=1,1,0) | AG13: https://www.infobae.com/colombia/2026/09/04/medicina-legal-confirmo-los-resultados-de-la-operacion-azarias-en-guaviare-en-la-que-murieron-23-disidentes-dos-eran-menores-de-edad/
A14: ART_001 | B14: ART_001_S07 | C14: Infobae Colombia | D14: Seguridad y orden público | E14: Noticia dura | F14: Fri, 04 Sep 2026 21:14:49 +0000 | G14: En cuanto a los procedimientos sobre los cuatro cuerpos pendientes, las identificaciones continuarán pese a las dificultades que presentan los cadáveres. | H14: El comunicado no detalló sus identidades, edades ni las circunstancias en las que murieron. | I14: Sin embargo, la institución no indicó un plazo para completar los registros. | AF14: =IF(COUNTIF($B$5:B14,B14)=1,1,0) | AG14: https://www.infobae.com/colombia/2026/09/04/medicina-legal-confirmo-los-resultados-de-la-operacion-azarias-en-guaviare-en-la-que-murieron-23-disidentes-dos-eran-menores-de-edad/
A15: ART_001 | B15: ART_001_S08 | C15: Infobae Colombia | D15: Seguridad y orden público | E15: Noticia dura | F15: Fri, 04 Sep 2026 21:14:49 +0000 | G15: Sin embargo, la institución no indicó un plazo para completar los registros. | H15: En cuanto a los procedimientos sobre los cuatro cuerpos pendientes, las identificaciones continuarán pese a las dificultades que presentan los cadáveres. | I15: En su pronunciamiento, el organismo afirmó que mantendrá su compromiso con la independencia técnica y la transparencia en apoyo a la administración de justicia. | AF15: =IF(COUNTIF($B$5:B15,B15)=1,1,0) | AG15: https://www.infobae.com/colombia/2026/09/04/medicina-legal-confirmo-los-resultados-de-la-operacion-azarias-en-guaviare-en-la-que-murieron-23-disidentes-dos-eran-menores-de-edad/
A16: ART_001 | B16: ART_001_S09 | C16: Infobae Colombia | D16: Seguridad y orden público | E16: Noticia dura | F16: Fri, 04 Sep 2026 21:14:49 +0000 | G16: En su pronunciamiento, el organismo afirmó que mantendrá su compromiso con la independencia técnica y la transparencia en apoyo a la administración de justicia. | H16: Sin embargo, la institución no indicó un plazo para completar los registros. | I16: El reporte de Medicina Legal se conoció cuatro días después de que el presidente Abelardo de la Espriella divulgara el resultado del operativo que incluyó bombardeos. | AF16: =IF(COUNTIF($B$5:B16,B16)=1,1,0) | AG16: https://www.infobae.com/colombia/2026/09/04/medicina-legal-confirmo-los-resultados-de-la-operacion-azarias-en-guaviare-en-la-que-murieron-23-disidentes-dos-eran-menores-de-edad/
A17: ART_001 | B17: ART_001_S10 | C17: Infobae Colombia | D17: Seguridad y orden público | E17: Noticia dura | F17: Fri, 04 Sep 2026 21:14:49 +0000 | G17: El reporte de Medicina Legal se conoció cuatro días después de que el presidente Abelardo de la Espriella divulgara el resultado del operativo que incluyó bombardeos. | H17: En su pronunciamiento, el organismo afirmó que mantendrá su compromiso con la independencia técnica y la transparencia en apoyo a la administración de justicia. | I17: Según el mandatario, durante la incursión murió alias El Tigre, a quien identificó como jefe del frente Carolina Ramírez, de las disidencias de las Farc. | AF17: =IF(COUNTIF($B$5:B17,B17)=1,1,0) | AG17: https://www.infobae.com/colombia/2026/09/04/medicina-legal-confirmo-los-resultados-de-la-operacion-azarias-en-guaviare-en-la-que-murieron-23-disidentes-dos-eran-menores-de-edad/
A18: ART_001 | B18: ART_001_S11 | C18: Infobae Colombia | D18: Seguridad y orden público | E18: Noticia dura | F18: Fri, 04 Sep 2026 21:14:49 +0000 | G18: Según el mandatario, durante la incursión murió alias El Tigre, a quien identificó como jefe del frente Carolina Ramírez, de las disidencias de las Farc. | H18: El reporte de Medicina Legal se conoció cuatro días después de que el presidente Abelardo de la Espriella divulgara el resultado del operativo que incluyó bombardeos. | I18: Esa estructura operaba bajo el mando de Néstor Gregorio Vera, alias Iván Mordisco, señalado por el Gobierno nacional como el hombre más buscado del país. | AF18: =IF(COUNTIF($B$5:B18,B18)=1,1,0) | AG18: https://www.infobae.com/colombia/2026/09/04/medicina-legal-confirmo-los-resultados-de-la-operacion-azarias-en-guaviare-en-la-que-murieron-23-disidentes-dos-eran-menores-de-edad/
A19: ART_001 | B19: ART_001_S12 | C19: Infobae Colombia | D19: Seguridad y orden público | E19: Noticia dura | F19: Fri, 04 Sep 2026 21:14:49 +0000 | G19: Esa estructura operaba bajo el mando de Néstor Gregorio Vera, alias Iván Mordisco, señalado por el Gobierno nacional como el hombre más buscado del país. | H19: Según el mandatario, durante la incursión murió alias El Tigre, a quien identificó como jefe del frente Carolina Ramírez, de las disidencias de las Farc. | AF19: =IF(COUNTIF($B$5:B19,B19)=1,1,0) | AG19: https://www.infobae.com/colombia/2026/09/04/medicina-legal-confirmo-los-resultados-de-la-operacion-azarias-en-guaviare-en-la-que-murieron-23-disidentes-dos-eran-menores-de-edad/
A20: ART_002 | B20: ART_002_S01 | C20: Infobae Colombia | D20: Transición de gobierno y relación con la oposición | E20: Noticia dura | F20: Fri, 04 Sep 2026 20:26:29 +0000 | G20: En medio de rumores, se confirmó que Naín Pérez Toncel, alias Bendito Menor, cabecilla de las Autodefensas Conquistadoras de la Sierra Nevada (Acsn), fue abatido en una operación militar ejecutada en el barrio Los Olivos de Riohacha, en el departamento de La Guajira. | I20: Desde el Batallón Cartagena de Riohacha, el presidente Abelardo de la Espriella se refirió a los hechos y aseguró que este resultado operacional responde a un trabajo conjunto de distintas instituciones de la fuerza pública. | AF20: =IF(COUNTIF($B$5:B20,B20)=1,1,0) | AG20: https://www.infobae.com/colombia/2026/09/04/autodefensas-conquistadoras-se-pronunciaron-sobre-la-muerte-del-cabecilla-bendito-menor-y-su-novia-la-bebecita-aseguraron-que-no-habra-represalias/
A21: ART_002 | B21: ART_002_S02 | C21: Infobae Colombia | D21: Transición de gobierno y relación con la oposición | E21: Noticia dura | F21: Fri, 04 Sep 2026 20:26:29 +0000 | G21: Desde el Batallón Cartagena de Riohacha, el presidente Abelardo de la Espriella se refirió a los hechos y aseguró que este resultado operacional responde a un trabajo conjunto de distintas instituciones de la fuerza pública. | H21: En medio de rumores, se confirmó que Naín Pérez Toncel, alias Bendito Menor, cabecilla de las Autodefensas Conquistadoras de la Sierra Nevada (Acsn), fue abatido en una operación militar ejecutada en el barrio Los Olivos de Riohacha, en el departamento de La Guajira. | I21: “Gracias a una operación impecable realizada por nuestra Policía Nacional, por un comando especial de la Dijín, se dio de baja a uno de los más peligrosos delincuentes de nuestro país (...). | AF21: =IF(COUNTIF($B$5:B21,B21)=1,1,0) | AG21: https://www.infobae.com/colombia/2026/09/04/autodefensas-conquistadoras-se-pronunciaron-sobre-la-muerte-del-cabecilla-bendito-menor-y-su-novia-la-bebecita-aseguraron-que-no-habra-represalias/
A22: ART_002 | B22: ART_002_S03 | C22: Infobae Colombia | D22: Transición de gobierno y relación con la oposición | E22: Noticia dura | F22: Fri, 04 Sep 2026 20:26:29 +0000 | G22: “Gracias a una operación impecable realizada por nuestra Policía Nacional, por un comando especial de la Dijín, se dio de baja a uno de los más peligrosos delincuentes de nuestro país (...). | H22: Desde el Batallón Cartagena de Riohacha, el presidente Abelardo de la Espriella se refirió a los hechos y aseguró que este resultado operacional responde a un trabajo conjunto de distintas instituciones de la fuerza pública. | I22: Hoy ha llegado el fin de las actividades criminales de este narcoterrorista que tenía azotada a La Guajira y al Caribe colombiano”, precisó el jefe de Estado en declaraciones públicas. | AF22: =IF(COUNTIF($B$5:B22,B22)=1,1,0) | AG22: https://www.infobae.com/colombia/2026/09/04/autodefensas-conquistadoras-se-pronunciaron-sobre-la-muerte-del-cabecilla-bendito-menor-y-su-novia-la-bebecita-aseguraron-que-no-habra-represalias/
A23: ART_002 | B23: ART_002_S04 | C23: Infobae Colombia | D23: Transición de gobierno y relación con la oposición | E23: Noticia dura | F23: Fri, 04 Sep 2026 20:26:29 +0000 | G23: Hoy ha llegado el fin de las actividades criminales de este narcoterrorista que tenía azotada a La Guajira y al Caribe colombiano”, precisó el jefe de Estado en declaraciones públicas. | H23: “Gracias a una operación impecable realizada por nuestra Policía Nacional, por un comando especial de la Dijín, se dio de baja a uno de los más peligrosos delincuentes de nuestro país (...). | I23: Por medio de un comunicado, las Acsn también confirmaron la muerte del peligroso cabecilla. | AF23: =IF(COUNTIF($B$5:B23,B23)=1,1,0) | AG23: https://www.infobae.com/colombia/2026/09/04/autodefensas-conquistadoras-se-pronunciaron-sobre-la-muerte-del-cabecilla-bendito-menor-y-su-novia-la-bebecita-aseguraron-que-no-habra-represalias/
A24: ART_002 | B24: ART_002_S05 | C24: Infobae Colombia | D24: Transición de gobierno y relación con la oposición | E24: Noticia dura | F24: Fri, 04 Sep 2026 20:26:29 +0000 | G24: Por medio de un comunicado, las Acsn también confirmaron la muerte del peligroso cabecilla. | H24: Hoy ha llegado el fin de las actividades criminales de este narcoterrorista que tenía azotada a La Guajira y al Caribe colombiano”, precisó el jefe de Estado en declaraciones públicas. | I24: “Lamentamos profundamente el fallecimiento de Naín Pérez Toncel, ocurrido en el marco de un operativo adelantado por la Fuerza Pública. | AF24: =IF(COUNTIF($B$5:B24,B24)=1,1,0) | AG24: https://www.infobae.com/colombia/2026/09/04/autodefensas-conquistadoras-se-pronunciaron-sobre-la-muerte-del-cabecilla-bendito-menor-y-su-novia-la-bebecita-aseguraron-que-no-habra-represalias/
A25: ART_002 | B25: ART_002_S06 | C25: Infobae Colombia | D25: Transición de gobierno y relación con la oposición | E25: Noticia dura | F25: Fri, 04 Sep 2026 20:26:29 +0000 | G25: “Lamentamos profundamente el fallecimiento de Naín Pérez Toncel, ocurrido en el marco de un operativo adelantado por la Fuerza Pública. | H25: Por medio de un comunicado, las Acsn también confirmaron la muerte del peligroso cabecilla. | I25: Se reconoce el impacto que este hecho representa para sus familiares, allegados y para las comunidades que han conocido de los acontecimientos registrados durante las últimas horas”, precisó la organización criminal en la comunicación oficial. | AF25: =IF(COUNTIF($B$5:B25,B25)=1,1,0) | AG25: https://www.infobae.com/colombia/2026/09/04/autodefensas-conquistadoras-se-pronunciaron-sobre-la-muerte-del-cabecilla-bendito-menor-y-su-novia-la-bebecita-aseguraron-que-no-habra-represalias/
A26: ART_002 | B26: ART_002_S07 | C26: Infobae Colombia | D26: Transición de gobierno y relación con la oposición | E26: Noticia dura | F26: Fri, 04 Sep 2026 20:26:29 +0000 | G26: Se reconoce el impacto que este hecho representa para sus familiares, allegados y para las comunidades que han conocido de los acontecimientos registrados durante las últimas horas”, precisó la organización criminal en la comunicación oficial. | H26: “Lamentamos profundamente el fallecimiento de Naín Pérez Toncel, ocurrido en el marco de un operativo adelantado por la Fuerza Pública. | I26: De igual manera, lamentó la muerte de Rosa Angélica Tarazona, alias La Bebecita, que era la pareja sentimental de alias Bendito Menor. | AF26: =IF(COUNTIF($B$5:B26,B26)=1,1,0) | AG26: https://www.infobae.com/colombia/2026/09/04/autodefensas-conquistadoras-se-pronunciaron-sobre-la-muerte-del-cabecilla-bendito-menor-y-su-novia-la-bebecita-aseguraron-que-no-habra-represalias/
A27: ART_002 | B27: ART_002_S08 | C27: Infobae Colombia | D27: Transición de gobierno y relación con la oposición | E27: Noticia dura | F27: Fri, 04 Sep 2026 20:26:29 +0000 | G27: De igual manera, lamentó la muerte de Rosa Angélica Tarazona, alias La Bebecita, que era la pareja sentimental de alias Bendito Menor. | H27: Se reconoce el impacto que este hecho representa para sus familiares, allegados y para las comunidades que han conocido de los acontecimientos registrados durante las últimas horas”, precisó la organización criminal en la comunicación oficial. | I27: Recientemente, el señalado criminal se había comprometido en matrimonio con la mujer en un evento romántico en la playa. | AF27: =IF(COUNTIF($B$5:B27,B27)=1,1,0) | AG27: https://www.infobae.com/colombia/2026/09/04/autodefensas-conquistadoras-se-pronunciaron-sobre-la-muerte-del-cabecilla-bendito-menor-y-su-novia-la-bebecita-aseguraron-que-no-habra-represalias/
A28: ART_002 | B28: ART_002_S09 | C28: Infobae Colombia | D28: Transición de gobierno y relación con la oposición | E28: Noticia dura | F28: Fri, 04 Sep 2026 20:26:29 +0000 | G28: Recientemente, el señalado criminal se había comprometido en matrimonio con la mujer en un evento romántico en la playa. | H28: De igual manera, lamentó la muerte de Rosa Angélica Tarazona, alias La Bebecita, que era la pareja sentimental de alias Bendito Menor. | I28: El grupo terrorista también informó que, aunque la operación militar ordenada por el Gobierno nacional supone una afectación para la organización al margen de la ley, no habrá retaliaciones de ningún tipo. | AF28: =IF(COUNTIF($B$5:B28,B28)=1,1,0) | AG28: https://www.infobae.com/colombia/2026/09/04/autodefensas-conquistadoras-se-pronunciaron-sobre-la-muerte-del-cabecilla-bendito-menor-y-su-novia-la-bebecita-aseguraron-que-no-habra-represalias/
A29: ART_002 | B29: ART_002_S10 | C29: Infobae Colombia | D29: Transición de gobierno y relación con la oposición | E29: Noticia dura | F29: Fri, 04 Sep 2026 20:26:29 +0000 | G29: El grupo terrorista también informó que, aunque la operación militar ordenada por el Gobierno nacional supone una afectación para la organización al margen de la ley, no habrá retaliaciones de ningún tipo. | H29: Recientemente, el señalado criminal se había comprometido en matrimonio con la mujer en un evento romántico en la playa. | I29: “Hacemos un llamado a la población civil de la Sierra Nevada de Santa Marta y de los departamentos del Magdalena, La Guajira y Cesar a mantener la calma. | AF29: =IF(COUNTIF($B$5:B29,B29)=1,1,0) | AG29: https://www.infobae.com/colombia/2026/09/04/autodefensas-conquistadoras-se-pronunciaron-sobre-la-muerte-del-cabecilla-bendito-menor-y-su-novia-la-bebecita-aseguraron-que-no-habra-represalias/
A30: ART_002 | B30: ART_002_S11 | C30: Infobae Colombia | D30: Transición de gobierno y relación con la oposición | E30: Noticia dura | F30: Fri, 04 Sep 2026 20:26:29 +0000 | G30: “Hacemos un llamado a la población civil de la Sierra Nevada de Santa Marta y de los departamentos del Magdalena, La Guajira y Cesar a mantener la calma. | H30: El grupo terrorista también informó que, aunque la operación militar ordenada por el Gobierno nacional supone una afectación para la organización al margen de la ley, no habrá retaliaciones de ningún tipo. | I30: Aunque es un golpe a nuestra organización, no habrá retaliaciones”, indicó el grupo armado. | AF30: =IF(COUNTIF($B$5:B30,B30)=1,1,0) | AG30: https://www.infobae.com/colombia/2026/09/04/autodefensas-conquistadoras-se-pronunciaron-sobre-la-muerte-del-cabecilla-bendito-menor-y-su-novia-la-bebecita-aseguraron-que-no-habra-represalias/
A31: ART_002 | B31: ART_002_S12 | C31: Infobae Colombia | D31: Transición de gobierno y relación con la oposición | E31: Noticia dura | F31: Fri, 04 Sep 2026 20:26:29 +0000 | G31: Aunque es un golpe a nuestra organización, no habrá retaliaciones”, indicó el grupo armado. | H31: “Hacemos un llamado a la población civil de la Sierra Nevada de Santa Marta y de los departamentos del Magdalena, La Guajira y Cesar a mantener la calma. | AF31: =IF(COUNTIF($B$5:B31,B31)=1,1,0) | AG31: https://www.infobae.com/colombia/2026/09/04/autodefensas-conquistadoras-se-pronunciaron-sobre-la-muerte-del-cabecilla-bendito-menor-y-su-novia-la-bebecita-aseguraron-que-no-habra-represalias/
A32: ART_003 | B32: ART_003_S01 | C32: Infobae Colombia | D32: Transición de gobierno y relación con la oposición | E32: Noticia dura | F32: Fri, 04 Sep 2026 18:20:11 +0000 | G32: La Alianza Verde salió a responder a las expresiones del senador del Pacto Histórico David Racero contra la representante de su partido Catherine Juvinao durante la discusión del Presupuesto General de la Nación (PGN) 2027 en las comisiones económicas del Congreso de la República. | I32: La colectividad “rechaza contundentemente la violencia política, verbal y simbólica” de la que, según afirma, ha sido víctima la congresista por parte del legislador del Pacto Histórico. | AF32: =IF(COUNTIF($B$5:B32,B32)=1,1,0) | AG32: https://www.infobae.com/colombia/2026/09/04/alianza-verde-critico-a-david-racero-por-llamar-lavaperros-a-catherine-juvinao-durante-la-discusion-del-presupuesto-general-de-la-nacion-violencia-politica-verbal-y-simbolica/
A33: ART_003 | B33: ART_003_S02 | C33: Infobae Colombia | D33: Transición de gobierno y relación con la oposición | E33: Noticia dura | F33: Fri, 04 Sep 2026 18:20:11 +0000 | G33: La colectividad “rechaza contundentemente la violencia política, verbal y simbólica” de la que, según afirma, ha sido víctima la congresista por parte del legislador del Pacto Histórico. | H33: La Alianza Verde salió a responder a las expresiones del senador del Pacto Histórico David Racero contra la representante de su partido Catherine Juvinao durante la discusión del Presupuesto General de la Nación (PGN) 2027 en las comisiones económicas del Congreso de la República. | AF33: =IF(COUNTIF($B$5:B33,B33)=1,1,0) | AG33: https://www.infobae.com/colombia/2026/09/04/alianza-verde-critico-a-david-racero-por-llamar-lavaperros-a-catherine-juvinao-durante-la-discusion-del-presupuesto-general-de-la-nacion-violencia-politica-verbal-y-simbolica/
A34: ART_004 | B34: ART_004_S01 | C34: Infobae Colombia | D34: Seguridad y orden público | E34: Noticia dura | F34: Fri, 04 Sep 2026 02:29:45 +0000 | G34: Ni la Presidencia de la República, ejercida por Abelardo de la Espriella, ni el Ministerio de Defensa, ni la fuerza pública, están autorizadas para ejecutar operaciones aéreas ofensivas en zonas donde se sospeche que hay presencia de niños, niñas y adolescentes reclutados por organizaciones criminales. | I34: Así lo determinó el Juzgado 34 de Familia de Bogotá en un fallo proferido el 2 de septiembre de 2026, por medio del cual decretó la medida provisional, en respuesta a una acción de tutela que está en estudio. | AF34: =IF(COUNTIF($B$5:B34,B34)=1,1,0) | AG34: https://www.infobae.com/colombia/2026/09/04/accionante-que-logro-que-un-juzgado-frenara-bombardeos-por-presencia-de-menores-explico-el-alcance-de-su-tutela-se-deben-proteger/
A35: ART_004 | B35: ART_004_S02 | C35: Infobae Colombia | D35: Seguridad y orden público | E35: Noticia dura | F35: Fri, 04 Sep 2026 02:29:45 +0000 | G35: Así lo determinó el Juzgado 34 de Familia de Bogotá en un fallo proferido el 2 de septiembre de 2026, por medio del cual decretó la medida provisional, en respuesta a una acción de tutela que está en estudio. | H35: Ni la Presidencia de la República, ejercida por Abelardo de la Espriella, ni el Ministerio de Defensa, ni la fuerza pública, están autorizadas para ejecutar operaciones aéreas ofensivas en zonas donde se sospeche que hay presencia de niños, niñas y adolescentes reclutados por organizaciones criminales. | AF35: =IF(COUNTIF($B$5:B35,B35)=1,1,0) | AG35: https://www.infobae.com/colombia/2026/09/04/accionante-que-logro-que-un-juzgado-frenara-bombardeos-por-presencia-de-menores-explico-el-alcance-de-su-tutela-se-deben-proteger/
A36: ART_005 | B36: ART_005_S01 | C36: El Tiempo | D36: Transición de gobierno y relación con la oposición | E36: Noticia dura | F36: 2026-09-04T16:36:43-05:00 | G36: La decisión de la Alianza Verde de declararse como partido independiente al gobierno de Abelardo De La Espriella ha generado polémica. | I36: No sólo dejó al Pacto Histórico y En Marcha como únicas fuerzas de oposición, sino que se ha llamado la atención debido a que el partido de centro pasó de ser uno de los grandes aliados de Gustavo Petro a no acompañar a su bancada en su postura frente a la nueva administración. | AF36: =IF(COUNTIF($B$5:B36,B36)=1,1,0) | AG36: https://www.eltiempo.com/politica/partidos-politicos/las-movidas-detras-de-la-declaratoria-de-la-alianza-verde-como-partido-independiente-al-gobierno-de-abelardo-de-la-espriella-3583710
A37: ART_005 | B37: ART_005_S02 | C37: El Tiempo | D37: Transición de gobierno y relación con la oposición | E37: Noticia dura | F37: 2026-09-04T16:36:43-05:00 | G37: No sólo dejó al Pacto Histórico y En Marcha como únicas fuerzas de oposición, sino que se ha llamado la atención debido a que el partido de centro pasó de ser uno de los grandes aliados de Gustavo Petro a no acompañar a su bancada en su postura frente a la nueva administración. | H37: La decisión de la Alianza Verde de declararse como partido independiente al gobierno de Abelardo De La Espriella ha generado polémica. | I37: Las críticas no se han hecho esperar. | AF37: =IF(COUNTIF($B$5:B37,B37)=1,1,0) | AG37: https://www.eltiempo.com/politica/partidos-politicos/las-movidas-detras-de-la-declaratoria-de-la-alianza-verde-como-partido-independiente-al-gobierno-de-abelardo-de-la-espriella-3583710
A38: ART_005 | B38: ART_005_S03 | C38: El Tiempo | D38: Transición de gobierno y relación con la oposición | E38: Noticia dura | F38: 2026-09-04T16:36:43-05:00 | G38: Las críticas no se han hecho esperar. | H38: No sólo dejó al Pacto Histórico y En Marcha como únicas fuerzas de oposición, sino que se ha llamado la atención debido a que el partido de centro pasó de ser uno de los grandes aliados de Gustavo Petro a no acompañar a su bancada en su postura frente a la nueva administración. | I38: “Frente al fascismo no se puede ser independiente”, dijo el excandidato presidencial y senador, Iván Cepeda. | AF38: =IF(COUNTIF($B$5:B38,B38)=1,1,0) | AG38: https://www.eltiempo.com/politica/partidos-politicos/las-movidas-detras-de-la-declaratoria-de-la-alianza-verde-como-partido-independiente-al-gobierno-de-abelardo-de-la-espriella-3583710
A39: ART_005 | B39: ART_005_S04 | C39: El Tiempo | D39: Transición de gobierno y relación con la oposición | E39: Noticia dura | F39: 2026-09-04T16:36:43-05:00 | G39: “Frente al fascismo no se puede ser independiente”, dijo el excandidato presidencial y senador, Iván Cepeda. | H39: Las críticas no se han hecho esperar. | I39: Y es que algunos no entienden la decisión y qué hay detrás de ella. | AF39: =IF(COUNTIF($B$5:B39,B39)=1,1,0) | AG39: https://www.eltiempo.com/politica/partidos-politicos/las-movidas-detras-de-la-declaratoria-de-la-alianza-verde-como-partido-independiente-al-gobierno-de-abelardo-de-la-espriella-3583710
A40: ART_005 | B40: ART_005_S05 | C40: El Tiempo | D40: Transición de gobierno y relación con la oposición | E40: Noticia dura | F40: 2026-09-04T16:36:43-05:00 | G40: Y es que algunos no entienden la decisión y qué hay detrás de ella. | H40: “Frente al fascismo no se puede ser independiente”, dijo el excandidato presidencial y senador, Iván Cepeda. | I40: Lo ven como una falta de coherencia frente a lo que ha predicado el partido durante su existencia. | AF40: =IF(COUNTIF($B$5:B40,B40)=1,1,0) | AG40: https://www.eltiempo.com/politica/partidos-politicos/las-movidas-detras-de-la-declaratoria-de-la-alianza-verde-como-partido-independiente-al-gobierno-de-abelardo-de-la-espriella-3583710
A41: ART_005 | B41: ART_005_S06 | C41: El Tiempo | D41: Transición de gobierno y relación con la oposición | E41: Noticia dura | F41: 2026-09-04T16:36:43-05:00 | G41: Lo ven como una falta de coherencia frente a lo que ha predicado el partido durante su existencia. | H41: Y es que algunos no entienden la decisión y qué hay detrás de ella. | I41: Además, han cuestionado que hasta hace unos días venía ganando la postura de la oposición y al final se revirtió la tendencia. | AF41: =IF(COUNTIF($B$5:B41,B41)=1,1,0) | AG41: https://www.eltiempo.com/politica/partidos-politicos/las-movidas-detras-de-la-declaratoria-de-la-alianza-verde-como-partido-independiente-al-gobierno-de-abelardo-de-la-espriella-3583710
...
